Workbook

Sheet 00_HuongDan
A1: TÍNH IRT 1PL (RASCH) BẰNG EXCEL — JMLE, công thức sống
A3: Dữ liệu: đề 4561803381 — 1037 học sinh × 48 item (24 trắc nghiệm MC + 24 ý Đúng/Sai TF).
A4: Mục đích: minh hoạ MINH BẠCH cách ước lượng độ khó b và năng lực θ của mô hình Rasch.
A6: MÔ HÌNH RASCH: P(θ) = 1 / (1 + e^-(θ - b)) — xác suất trả lời đúng (mục 1.4 tài liệu lý thuyết).
A8: PHƯƠNG PHÁP JMLE (Joint Maximum Likelihood) — lặp Newton, xem '03_Lap_JMLE_*':
A9: Khởi tạo (log-odds): b0 = ln((Nsai+0.3)/(Nđúng+0.3)), θ0 = ln((R+0.3)/(M-R+0.3)); rồi canh tâm b ← b - mean(b).
A10: Mỗi vòng:
A11: θ ← θ + (R - ΣP) / Σ P(1-P) (cập nhật năng lực từng HS; R=điểm, tổng trên câu ĐÃ làm)
A12: b ← b + (ΣP - S) / Σ P(1-P) (cập nhật độ khó từng item; S=số HS đúng) → canh tâm b ← b - mean(b)
A13: Mẹo Excel: Σ P(1-P) không cần lưới riêng — dùng SUMPRODUCT gói P; ô trống tự bị loại nhờ điều kiện (ô <> "").
A15: ĐỘ CHÍNH XÁC (mục 1.7): Thông tin I(θ)=Σ P(1-P); Sai số chuẩn SE(θ)=1/√I(θ). Tương tự SE(b)=1/√Σ P(1-P).
A17: ĐIỂM THỰC / TCC (mục 3.6): τ(θ)=Σ P_j(θ) = kỳ vọng số câu đúng; đường TCC nối thang θ (trừu tượng) với 'số câu đúng' (quen thuộc).
... A36: • 2PL/3PL KHÔNG dựng trong Excel thuần (phải ước lượng độ phân biệt a / đoán mò c từng câu) — chỉ làm 1PL.

Sheet 01_Data
A1: iduser | B1: 208493209536 | C1: 208493412207 | D1: 208493634375 | E1: 208493806712 | F1: 208494503646 | G1: 208495066643 | H1: 208495459130 | I1: 208495984573 | J1: 208496326564 | K1: 208497043631 | L1: 208497697530 | M1: 208497947837 | N1: 208498680706 | O1: 208498750254 | P1: 208500103341 | Q1: 208500538567 | R1: 208501397853 | S1: 208501882621 | T1: 208502464537 | U1: 208518915377 | V1: 208519541200 | W1: 208519949207 | X1: 208520832930 | Y1: 208521276474 | Z1: 208529022568_a | AA1: 208529022568_b | AB1: 208529022568_c | AC1: 208529022568_d | AD1: 208560377855_a | AE1: 208560377855_b | AF1: 208560377855_c | AG1: 208560377855_d | AH1: 208572448723_a | AI1: 208572448723_b | AJ1: 208572448723_c | AK1: 208572448723_d | AL1: 208572588199_a | AM1: 208572588199_b | AN1: 208572588199_c | AO1: 208572588199_d | AP1: 208572673790_a | AQ1: 208572673790_b | AR1: 208572673790_c | AS1: 208572673790_d | AT1: 208576851532_a | AU1: 208576851532_b | AV1: 208576851532_c | AW1: 208576851532_d
A2: 15540277583874 | B2: 1 | C2: 0 | D2: 1 | E2: 1 | F2: 1 | G2: 0 | H2: 1 | I2: 0 | J2: 1 | K2: 0 | L2: 1 | M2: 0 | N2: 0 | O2: 1 | P2: 0 | Q2: 0 | R2: 0 | S2: 0 | T2: 0 | U2: 0 | V2: 0 | W2: 0 | X2: 0 | Y2: 0 | Z2: 0 | AA2: 0 | AB2: 0 | AC2: 0 | AD2: 0 | AE2: 0 | AF2: 0 | AG2: 0 | AH2: 0 | AI2: 0 | AJ2: 0 | AK2: 0 | AL2: 0 | AM2: 0 | AN2: 0 | AO2: 0
A3: 15764388581922 | B3: 1 | C3: 1 | D3: 0 | E3: 1 | F3: 1 | G3: 1 | H3: 1 | I3: 1 | J3: 1 | K3: 0 | L3: 1 | M3: 1 | N3: 1 | O3: 1 | P3: 1 | Q3: 1 | R3: 1 | S3: 1 | T3: 1 | U3: 1 | V3: 1 | W3: 1 | X3: 1 | Y3: 1 | Z3: 1 | AA3: 1 | AB3: 1 | AC3: 1 | AH3: 1 | AI3: 1 | AJ3: 1 | AK3: 1 | AP3: 0 | AQ3: 0 | AR3: 0 | AS3: 1 | AT3: 1 | AU3: 1 | AV3: 1 | AW3: 1
A4: 15764389367618 | B4: 1 | C4: 1 | D4: 0 | E4: 1 | F4: 1 | G4: 1 | H4: 1 | I4: 1 | J4: 1 | K4: 0 | L4: 1 | M4: 1 | N4: 1 | O4: 1 | P4: 1 | Q4: 0 | R4: 1 | S4: 1 | T4: 1 | U4: 0 | V4: 1 | W4: 0 | X4: 0 | Y4: 1 | Z4: 1 | AA4: 1 | AB4: 1 | AC4: 1 | AD4: 1 | AE4: 1 | AF4: 1 | AG4: 1 | AH4: 1 | AI4: 1 | AJ4: 1 | AK4: 1 | AL4: 1 | AM4: 1 | AN4: 1 | AO4: 1
A5: 15764389862692 | B5: 1 | C5: 1 | D5: 1 | E5: 1 | F5: 1 | G5: 1 | H5: 1 | I5: 1 | J5: 1 | K5: 1 | L5: 1 | M5: 1 | N5: 1 | O5: 1 | P5: 1 | Q5: 1 | R5: 1 | S5: 0 | T5: 1 | U5: 1 | V5: 1 | W5: 1 | X5: 1 | Y5: 0 | Z5: 1 | AA5: 1 | AB5: 1 | AC5: 1 | AH5: 1 | AI5: 0 | AJ5: 1 | AK5: 1 | AP5: 0 | AQ5: 1 | AR5: 0 | AS5: 0 | AT5: 1 | AU5: 1 | AV5: 1 | AW5: 1
A6: 15764390159150 | B6: 1 | C6: 0 | D6: 0 | E6: 1 | F6: 1 | G6: 1 | H6: 0 | I6: 1 | J6: 1 | K6: 1 | L6: 1 | M6: 1 | N6: 1 | O6: 0 | P6: 1 | Q6: 0 | R6: 1 | S6: 1 | T6: 1 | U6: 1 | V6: 1 | W6: 0 | X6: 1 | Y6: 0 | Z6: 1 | AA6: 1 | AB6: 1 | AC6: 1 | AH6: 1 | AI6: 1 | AJ6: 1 | AK6: 1 | AP6: 0 | AQ6: 0 | AR6: 0 | AS6: 1 | AT6: 1 | AU6: 1 | AV6: 1 | AW6: 1
A7: 15764390311756 | B7: 1 | C7: 0 | D7: 1 | E7: 1 | F7: 1 | G7: 0 | H7: 0 | I7: 1 | J7: 1 | K7: 1 | L7: 1 | M7: 1 | N7: 1 | O7: 1 | P7: 1 | Q7: 0 | R7: 1 | S7: 1 | T7: 0 | U7: 1 | V7: 1 | W7: 0 | X7: 0 | Y7: 1 | Z7: 1 | AA7: 1 | AB7: 1 | AC7: 1 | AH7: 1 | AI7: 1 | AJ7: 1 | AK7: 0 | AP7: 0 | AQ7: 1 | AR7: 0 | AS7: 0 | AT7: 1 | AU7: 0 | AV7: 0 | AW7: 1
A8: 15764390467409 | B8: 1 | C8: 0 | D8: 0 | E8: 1 | F8: 0 | G8: 0 | H8: 0 | I8: 1 | J8: 1 | K8: 1 | L8: 1 | M8: 1 | N8: 1 | O8: 1 | P8: 0 | Q8: 0 | R8: 0 | S8: 0 | T8: 0 | U8: 1 | V8: 1 | W8: 0 | X8: 0 | Y8: 0 | Z8: 1 | AA8: 1 | AB8: 1 | AC8: 1 | AH8: 1 | AI8: 0 | AJ8: 0 | AK8: 0 | AP8: 1 | AQ8: 1 | AR8: 0 | AS8: 1 | AT8: 1 | AU8: 0 | AV8: 1 | AW8: 1
A9: 15764391262752 | B9: 1 | C9: 1 | D9: 1 | E9: 1 | F9: 1 | G9: 1 | H9: 1 | I9: 1 | J9: 1 | K9: 0 | L9: 1 | M9: 0 | N9: 1 | O9: 1 | P9: 1 | Q9: 1 | R9: 1 | S9: 0 | T9: 1 | U9: 0 | V9: 1 | W9: 1 | X9: 0 | Y9: 1 | Z9: 1 | AA9: 1 | AB9: 1 | AC9: 1 | AH9: 0 | AI9: 0 | AJ9: 0 | AK9: 0 | AP9: 0 | AQ9: 1 | AR9: 0 | AS9: 0 | AT9: 1 | AU9: 1 | AV9: 1 | AW9: 0
A10: 15764391798843 | B10: 1 | C10: 1 | D10: 1 | E10: 1 | F10: 1 | G10: 1 | H10: 1 | I10: 1 | J10: 1 | K10: 1 | L10: 1 | M10: 0 | N10: 1 | O10: 1 | P10: 0 | Q10: 0 | R10: 1 | S10: 1 | T10: 1 | U10: 1 | V10: 0 | W10: 1 | X10: 1 | Y10: 1 | Z10: 1 | AA10: 1 | AB10: 1 | AC10: 1 | AH10: 1 | AI10: 1 | AJ10: 1 | AK10: 1 | AP10: 1 | AQ10: 1 | AR10: 0 | AS10: 0 | AT10: 1 | AU10: 1 | AV10: 1 | AW10: 1
A11: 15804254532858 | B11: 1 | C11: 0 | D11: 1 | E11: 0 | F11: 0 | G11: 0 | H11: 0 | I11: 1 | J11: 1 | K11: 1 | L11: 1 | M11: 0 | N11: 1 | O11: 1 | P11: 0 | Q11: 0 | R11: 1 | S11: 1 | T11: 1 | U11: 0 | V11: 1 | W11: 0 | X11: 0 | Y11: 1 | Z11: 0 | AA11: 1 | AB11: 0 | AC11: 1 | AD11: 0 | AE11: 0 | AF11: 0 | AG11: 0 | AH11: 1 | AI11: 0 | AJ11: 0 | AK11: 1 | AL11: 0 | AM11: 0 | AN11: 0 | AO11: 0
A12: 15807473377907 | B12: 1 | C12: 0 | D12: 1 | E12: 1 | F12: 1 | G12: 0 | H12: 0 | I12: 1 | J12: 1 | K12: 1 | L12: 1 | M12: 1 | N12: 1 | O12: 0 | P12: 0 | Q12: 1 | R12: 1 | S12: 1 | T12: 1 | U12: 0 | V12: 0 | W12: 0 | X12: 0 | Y12: 0 | Z12: 1 | AA12: 0 | AB12: 0 | AC12: 0 | AH12: 1 | AI12: 0 | AJ12: 1 | AK12: 1 | AP12: 1 | AQ12: 1 | AR12: 0 | AS12: 1 | AT12: 1 | AU12: 1 | AV12: 1 | AW12: 1
A13: 15811404757372 | B13: 1 | C13: 0 | D13: 0 | E13: 1 | F13: 1 | G13: 0 | H13: 1 | I13: 1 | J13: 1 | K13: 0 | L13: 1 | M13: 0 | N13: 1 | O13: 1 | P13: 0 | Q13: 0 | R13: 1 | S13: 1 | T13: 0 | U13: 0 | V13: 0 | W13: 0 | X13: 0 | Y13: 0 | Z13: 0 | AA13: 0 | AB13: 0 | AC13: 0 | AD13: 0 | AE13: 0 | AF13: 0 | AG13: 0 | AH13: 0 | AI13: 0 | AJ13: 0 | AK13: 0 | AL13: 0 | AM13: 0 | AN13: 0 | AO13: 0
A14: 15813817884992 | B14: 1 | C14: 0 | D14: 1 | E14: 1 | F14: 1 | G14: 1 | H14: 1 | I14: 0 | J14: 1 | K14: 1 | L14: 1 | M14: 1 | N14: 1 | O14: 1 | P14: 0 | Q14: 1 | R14: 1 | S14: 1 | T14: 1 | U14: 1 | V14: 1 | W14: 0 | X14: 0 | Y14: 0 | Z14: 1 | AA14: 1 | AB14: 1 | AC14: 1 | AH14: 1 | AI14: 1 | AJ14: 1 | AK14: 1 | AP14: 0 | AQ14: 1 | AR14: 0 | AS14: 1 | AT14: 1 | AU14: 1 | AV14: 1 | AW14: 1
A15: 15813834176636 | B15: 1 | C15: 1 | D15: 1 | E15: 1 | F15: 0 | G15: 1 | H15: 1 | I15: 0 | J15: 1 | K15: 1 | L15: 1 | M15: 1 | N15: 1 | O15: 1 | P15: 0 | Q15: 1 | R15: 1 | S15: 1 | T15: 0 | U15: 1 | V15: 1 | W15: 1 | X15: 1 | Y15: 0 | Z15: 0 | AA15: 1 | AB15: 1 | AC15: 0 | AH15: 1 | AI15: 1 | AJ15: 0 | AK15: 1 | AP15: 0 | AQ15: 0 | AR15: 0 | AS15: 1 | AT15: 1 | AU15: 0 | AV15: 0 | AW15: 1
A16: 15813834515232 | B16: 1 | C16: 0 | D16: 0 | E16: 1 | F16: 1 | G16: 0 | H16: 0 | I16: 0 | J16: 1 | K16: 1 | L16: 1 | M16: 1 | N16: 1 | O16: 0 | P16: 0 | Q16: 0 | R16: 1 | S16: 1 | T16: 1 | U16: 0 | V16: 1 | W16: 0 | X16: 0 | Y16: 0 | Z16: 0 | AA16: 1 | AB16: 1 | AC16: 1 | AH16: 1 | AI16: 1 | AJ16: 0 | AK16: 0 | AP16: 1 | AQ16: 1 | AR16: 0 | AS16: 1 | AT16: 1 | AU16: 1 | AV16: 1 | AW16: 1
A17: 15813835269355 | B17: 1 | C17: 0 | D17: 1 | E17: 1 | F17: 1 | G17: 0 | H17: 0 | I17: 1 | J17: 1 | K17: 0 | L17: 1 | M17: 1 | N17: 1 | O17: 1 | P17: 1 | Q17: 1 | R17: 1 | S17: 0 | T17: 1 | U17: 1 | V17: 1 | W17: 1 | X17: 1 | Y17: 0 | Z17: 1 | AA17: 1 | AB17: 1 | AC17: 1 | AH17: 1 | AI17: 1 | AJ17: 0 | AK17: 1 | AP17: 0 | AQ17: 1 | AR17: 0 | AS17: 0 | AT17: 1 | AU17: 1 | AV17: 1 | AW17: 1
A18: 15813836152589 | B18: 1 | C18: 1 | D18: 1 | E18: 1 | F18: 1 | G18: 1 | H18: 1 | I18: 1 | J18: 1 | K18: 0 | L18: 1 | M18: 1 | N18: 1 | O18: 0 | P18: 1 | Q18: 1 | R18: 1 | S18: 0 | T18: 1 | U18: 0 | V18: 1 | W18: 0 | X18: 0 | Y18: 0 | Z18: 1 | AA18: 1 | AB18: 1 | AC18: 1 | AD18: 0 | AE18: 0 | AF18: 0 | AG18: 0 | AH18: 1 | AI18: 1 | AJ18: 1 | AK18: 1 | AL18: 0 | AM18: 0 | AN18: 0 | AO18: 0
A19: 15813836418152 | B19: 1 | C19: 1 | D19: 1 | E19: 1 | F19: 1 | G19: 1 | H19: 1 | I19: 1 | J19: 1 | K19: 1 | L19: 1 | M19: 0 | N19: 1 | O19: 0 | P19: 1 | Q19: 0 | R19: 1 | S19: 1 | T19: 1 | U19: 1 | V19: 1 | W19: 1 | X19: 0 | Y19: 0 | Z19: 1 | AA19: 1 | AB19: 1 | AC19: 1 | AH19: 1 | AI19: 1 | AJ19: 1 | AK19: 1 | AP19: 0 | AQ19: 1 | AR19: 0 | AS19: 1 | AT19: 1 | AU19: 1 | AV19: 1 | AW19: 1
A20: 15813836562925 | B20: 1 | C20: 1 | D20: 1 | E20: 0 | F20: 0 | G20: 1 | H20: 1 | I20: 1 | J20: 1 | K20: 1 | L20: 0 | M20: 0 | N20: 1 | O20: 1 | P20: 1 | Q20: 0 | R20: 1 | S20: 1 | T20: 0 | U20: 0 | V20: 0 | W20: 1 | X20: 1 | Y20: 0 | Z20: 0 | AA20: 1 | AB20: 0 | AC20: 1 | AH20: 1 | AI20: 0 | AJ20: 0 | AK20: 1 | AP20: 0 | AQ20: 1 | AR20: 0 | AS20: 1 | AT20: 1 | AU20: 0 | AV20: 1 | AW20: 1
A21: 15813836698625 | B21: 1 | C21: 1 | D21: 1 | E21: 1 | F21: 1 | G21: 1 | H21: 0 | I21: 1 | J21: 1 | K21: 1 | L21: 1 | M21: 1 | N21: 1 | O21: 1 | P21: 1 | Q21: 1 | R21: 1 | S21: 1 | T21: 1 | U21: 0 | V21: 1 | W21: 1 | X21: 1 | Y21: 1 | Z21: 1 | AA21: 1 | AB21: 0 | AC21: 1 | AH21: 1 | AI21: 0 | AJ21: 1 | AK21: 1 | AP21: 1 | AQ21: 1 | AR21: 0 | AS21: 1 | AT21: 1 | AU21: 1 | AV21: 1 | AW21: 1
A22: 15813836853037 | B22: 1 | C22: 1 | D22: 0 | E22: 1 | F22: 1 | G22: 1 | H22: 1 | I22: 1 | J22: 1 | K22: 0 | L22: 1 | M22: 1 | N22: 1 | O22: 1 | P22: 1 | Q22: 1 | R22: 1 | S22: 1 | T22: 1 | U22: 0 | V22: 1 | W22: 1 | X22: 1 | Y22: 1 | Z22: 1 | AA22: 1 | AB22: 1 | AC22: 1 | AH22: 1 | AI22: 1 | AJ22: 1 | AK22: 1 | AP22: 0 | AQ22: 1 | AR22: 0 | AS22: 1 | AT22: 1 | AU22: 1 | AV22: 1 | AW22: 1
A23: 15813836942213 | B23: 0 | C23: 0 | D23: 0 | E23: 0 | F23: 0 | G23: 0 | H23: 0 | I23: 0 | J23: 0 | K23: 0 | L23: 0 | M23: 0 | N23: 0 | O23: 0 | P23: 0 | Q23: 0 | R23: 0 | S23: 0 | T23: 0 | U23: 0 | V23: 0 | W23: 0 | X23: 0 | Y23: 0 | Z23: 0 | AA23: 0 | AB23: 0 | AC23: 0 | AD23: 0 | AE23: 0 | AF23: 0 | AG23: 0 | AH23: 0 | AI23: 0 | AJ23: 0 | AK23: 0 | AL23: 0 | AM23: 0 | AN23: 0 | AO23: 0
A24: 15813837029549 | B24: 0 | C24: 0 | D24: 0 | E24: 1 | F24: 1 | G24: 0 | H24: 0 | I24: 0 | J24: 0 | K24: 0 | L24: 1 | M24: 0 | N24: 1 | O24: 0 | P24: 1 | Q24: 1 | R24: 1 | S24: 1 | T24: 0 | U24: 0 | V24: 1 | W24: 1 | X24: 0 | Y24: 1 | Z24: 1 | AA24: 1 | AB24: 1 | AC24: 1 | AH24: 1 | AI24: 1 | AJ24: 0 | AK24: 1 | AP24: 0 | AQ24: 1 | AR24: 1 | AS24: 1 | AT24: 1 | AU24: 0 | AV24: 0 | AW24: 0
A25: 15813837425218 | B25: 0 | C25: 0 | D25: 1 | E25: 0 | F25: 1 | G25: 1 | H25: 0 | I25: 1 | J25: 1 | K25: 1 | L25: 1 | M25: 0 | N25: 1 | O25: 0 | P25: 0 | Q25: 0 | R25: 1 | S25: 0 | T25: 0 | U25: 0 | V25: 1 | W25: 0 | X25: 0 | Y25: 0 | Z25: 0 | AA25: 0 | AB25: 0 | AC25: 1 | AH25: 1 | AI25: 0 | AJ25: 1 | AK25: 0 | AP25: 1 | AQ25: 0 | AR25: 0 | AS25: 1 | AT25: 1 | AU25: 1 | AV25: 1 | AW25: 1
A26: 15813837549840 | B26: 0 | C26: 1 | D26: 0 | E26: 1 | F26: 1 | G26: 1 | H26: 1 | I26: 1 | J26: 1 | K26: 1 | L26: 1 | M26: 0 | N26: 1 | O26: 1 | P26: 0 | Q26: 0 | R26: 1 | S26: 0 | T26: 1 | U26: 1 | V26: 1 | W26: 0 | X26: 1 | Y26: 1 | Z26: 1 | AA26: 1 | AB26: 0 | AC26: 1 | AH26: 1 | AI26: 1 | AJ26: 0 | AK26: 1 | AP26: 0 | AQ26: 1 | AR26: 1 | AS26: 1 | AT26: 1 | AU26: 0 | AV26: 1 | AW26: 0
A27: 15813837731418 | B27: 1 | C27: 0 | D27: 1 | E27: 0 | F27: 0 | G27: 0 | H27: 1 | I27: 1 | J27: 1 | K27: 1 | L27: 1 | M27: 0 | N27: 1 | O27: 1 | P27: 0 | Q27: 1 | R27: 1 | S27: 1 | T27: 1 | U27: 0 | V27: 1 | W27: 0 | X27: 0 | Y27: 0 | Z27: 1 | AA27: 1 | AB27: 0 | AC27: 0 | AH27: 1 | AI27: 0 | AJ27: 0 | AK27: 1 | AP27: 1 | AQ27: 0 | AR27: 0 | AS27: 1 | AT27: 1 | AU27: 0 | AV27: 1 | AW27: 1
A28: 15813837911584 | B28: 1 | C28: 1 | D28: 0 | E28: 1 | F28: 1 | G28: 1 | H28: 1 | I28: 1 | J28: 1 | K28: 1 | L28: 1 | M28: 0 | N28: 1 | O28: 1 | P28: 1 | Q28: 1 | R28: 1 | S28: 1 | T28: 1 | U28: 0 | V28: 1 | W28: 1 | X28: 1 | Y28: 1 | Z28: 0 | AA28: 0 | AB28: 1 | AC28: 1 | AH28: 1 | AI28: 0 | AJ28: 0 | AK28: 0 | AP28: 1 | AQ28: 0 | AR28: 1 | AS28: 1 | AT28: 1 | AU28: 0 | AV28: 0 | AW28: 0
A29: 15813838066017 | B29: 1 | C29: 0 | D29: 1 | E29: 0 | F29: 0 | G29: 1 | H29: 1 | I29: 1 | J29: 1 | K29: 1 | L29: 1 | M29: 0 | N29: 1 | O29: 0 | P29: 0 | Q29: 0 | R29: 0 | S29: 0 | T29: 0 | U29: 0 | V29: 1 | W29: 0 | X29: 0 | Y29: 1 | Z29: 0 | AA29: 1 | AB29: 1 | AC29: 1 | AH29: 1 | AI29: 1 | AJ29: 0 | AK29: 1 | AP29: 1 | AQ29: 1 | AR29: 0 | AS29: 1 | AT29: 1 | AU29: 1 | AV29: 1 | AW29: 1
A30: 15813838164392 | B30: 1 | C30: 0 | D30: 0 | E30: 1 | F30: 1 | G30: 0 | H30: 0 | I30: 0 | J30: 1 | K30: 1 | L30: 0 | M30: 1 | N30: 0 | O30: 0 | P30: 0 | Q30: 1 | R30: 1 | S30: 1 | T30: 0 | U30: 0 | V30: 1 | W30: 1 | X30: 0 | Y30: 0 | Z30: 0 | AA30: 1 | AB30: 1 | AC30: 1 | AH30: 0 | AI30: 1 | AJ30: 0 | AK30: 1 | AP30: 0 | AQ30: 0 | AR30: 0 | AS30: 1 | AT30: 1 | AU30: 1 | AV30: 1 | AW30: 1
A31: 15813838212711 | B31: 0 | C31: 1 | D31: 0 | E31: 0 | F31: 0 | G31: 0 | H31: 1 | I31: 1 | J31: 0 | K31: 0 | L31: 0 | M31: 1 | N31: 1 | O31: 0 | P31: 0 | Q31: 0 | R31: 0 | S31: 0 | T31: 1 | U31: 1 | V31: 0 | W31: 0 | X31: 1 | Y31: 0 | Z31: 0 | AA31: 1 | AB31: 0 | AC31: 1 | AH31: 0 | AI31: 0 | AJ31: 0 | AK31: 0 | AP31: 1 | AQ31: 1 | AR31: 0 | AS31: 1 | AT31: 0 | AU31: 0 | AV31: 1 | AW31: 0
A32: 15813838376485 | B32: 1 | C32: 0 | D32: 1 | E32: 1 | F32: 1 | G32: 1 | H32: 1 | I32: 1 | J32: 1 | K32: 1 | L32: 1 | M32: 1 | N32: 1 | O32: 1 | P32: 1 | Q32: 1 | R32: 1 | S32: 1 | T32: 0 | U32: 1 | V32: 1 | W32: 1 | X32: 1 | Y32: 0 | Z32: 1 | AA32: 1 | AB32: 1 | AC32: 1 | AH32: 1 | AI32: 1 | AJ32: 0 | AK32: 1 | AP32: 0 | AQ32: 1 | AR32: 1 | AS32: 0 | AT32: 1 | AU32: 1 | AV32: 1 | AW32: 1
A33: 15813838581109 | B33: 0 | C33: 0 | D33: 1 | E33: 1 | F33: 1 | G33: 0 | H33: 0 | I33: 0 | J33: 1 | K33: 1 | L33: 1 | M33: 0 | N33: 1 | O33: 1 | P33: 0 | Q33: 0 | R33: 0 | S33: 1 | T33: 0 | U33: 0 | V33: 1 | W33: 0 | X33: 0 | Y33: 0 | Z33: 0 | AA33: 1 | AB33: 0 | AC33: 1 | AH33: 1 | AI33: 0 | AJ33: 0 | AK33: 1 | AP33: 0 | AQ33: 1 | AR33: 0 | AS33: 1 | AT33: 1 | AU33: 0 | AV33: 1 | AW33: 1
A34: 15813838636693 | B34: 1 | C34: 0 | D34: 0 | E34: 1 | F34: 1 | G34: 0 | H34: 0 | I34: 0 | J34: 1 | K34: 1 | L34: 1 | M34: 1 | N34: 1 | O34: 0 | P34: 0 | Q34: 1 | R34: 1 | S34: 0 | T34: 1 | U34: 0 | V34: 1 | W34: 0 | X34: 1 | Y34: 0 | Z34: 1 | AA34: 1 | AB34: 1 | AC34: 0 | AH34: 1 | AI34: 1 | AJ34: 0 | AK34: 1 | AP34: 0 | AQ34: 1 | AR34: 0 | AS34: 1 | AT34: 1 | AU34: 1 | AV34: 1 | AW34: 1
A35: 15813838912964 | B35: 0 | C35: 0 | D35: 0 | E35: 0 | F35: 0 | G35: 0 | H35: 1 | I35: 0 | J35: 1 | K35: 0 | L35: 1 | M35: 0 | N35: 1 | O35: 0 | P35: 1 | Q35: 0 | R35: 1 | S35: 0 | T35: 1 | U35: 0 | V35: 0 | W35: 1 | X35: 0 | Y35: 0 | Z35: 0 | AA35: 1 | AB35: 0 | AC35: 1 | AH35: 1 | AI35: 0 | AJ35: 0 | AK35: 1 | AP35: 0 | AQ35: 1 | AR35: 1 | AS35: 0 | AT35: 1 | AU35: 0 | AV35: 1 | AW35: 0
... A49: 15813843373126 | B49: 1 | C49: 1 | D49: 1 | E49: 0 | F49: 1 | G49: 0 | H49: 0 | I49: 0 | J49: 1 | K49: 1 | L49: 1 | M49: 1 | N49: 1 | O49: 1 | P49: 0 | Q49: 0 | R49: 1 | S49: 1 | T49: 0 | U49: 0 | V49: 0 | W49: 0 | X49: 0 | Y49: 0 | Z49: 1 | AA49: 0 | AB49: 0 | AC49: 1 | AH49: 1 | AI49: 0 | AJ49: 0 | AK49: 0 | AP49: 1 | AQ49: 1 | AR49: 1 | AS49: 1 | AT49: 1 | AU49: 0 | AV49: 1 | AW49: 1
A50: 15813845765482 | B50: 0 | C50: 0 | D50: 0 | E50: 0 | F50: 0 | G50: 0 | H50: 0 | I50: 0 | J50: 1 | K50: 0 | L50: 1 | M50: 0 | N50: 0 | O50: 0 | P50: 0 | Q50: 0 | R50: 1 | S50: 0 | T50: 0 | U50: 0 | V50: 0 | W50: 0 | X50: 0 | Y50: 0 | Z50: 0 | AA50: 0 | AB50: 0 | AC50: 0 | AD50: 0 | AE50: 0 | AF50: 0 | AG50: 0 | AH50: 0 | AI50: 0 | AJ50: 0 | AK50: 0 | AL50: 0 | AM50: 0 | AN50: 0 | AO50: 0
A51: 15813864363687 | B51: 1 | C51: 1 | D51: 1 | E51: 1 | F51: 1 | G51: 1 | H51: 1 | I51: 0 | J51: 1 | K51: 1 | L51: 1 | M51: 1 | N51: 1 | O51: 1 | P51: 0 | Q51: 1 | R51: 1 | S51: 1 | T51: 1 | U51: 1 | V51: 1 | W51: 1 | X51: 1 | Y51: 1 | Z51: 1 | AA51: 1 | AB51: 1 | AC51: 1 | AH51: 1 | AI51: 1 | AJ51: 1 | AK51: 1 | AP51: 0 | AQ51: 1 | AR51: 0 | AS51: 1 | AT51: 1 | AU51: 0 | AV51: 1 | AW51: 1
A52: 15813867832894 | B52: 1 | C52: 0 | D52: 1 | E52: 1 | F52: 0 | G52: 1 | H52: 0 | I52: 0 | J52: 1 | K52: 1 | L52: 1 | M52: 0 | N52: 1 | O52: 1 | P52: 0 | Q52: 0 | R52: 1 | S52: 1 | T52: 0 | U52: 1 | V52: 0 | W52: 0 | X52: 1 | Y52: 1 | Z52: 0 | AA52: 1 | AB52: 0 | AC52: 0 | AD52: 0 | AE52: 0 | AF52: 0 | AG52: 0 | AH52: 0 | AI52: 1 | AJ52: 0 | AK52: 1 | AL52: 0 | AM52: 0 | AN52: 0 | AO52: 0
A53: 15813868065255 | B53: 1 | C53: 1 | D53: 0 | E53: 1 | F53: 1 | G53: 1 | H53: 0 | I53: 1 | J53: 1 | K53: 1 | L53: 1 | M53: 1 | N53: 1 | O53: 1 | P53: 1 | Q53: 1 | R53: 1 | S53: 1 | T53: 0 | U53: 0 | V53: 1 | W53: 1 | X53: 1 | Y53: 0 | Z53: 0 | AA53: 1 | AB53: 1 | AC53: 0 | AH53: 1 | AI53: 0 | AJ53: 0 | AK53: 0 | AP53: 1 | AQ53: 0 | AR53: 0 | AS53: 1 | AT53: 1 | AU53: 0 | AV53: 0 | AW53: 1
...

Sheet 02_KhoiTao
A1: i | B1: qid | C1: Câu | D1: Loại | E1: S (đúng) | F1: N (làm) | G1: p | H1: b0_raw=ln((N-S+.3)/(S+.3)) | I1: b0 (canh tâm) | J1: Biên?
A2: 1 | B2: 208493209536 | C2: Câu 1 MC | D2: MC | E2: =SUM('01_Data'!B2:B1038) | F2: =COUNT('01_Data'!B2:B1038) | G2: =E2/F2 | H2: =LN((F2-E2+0.3)/(E2+0.3)) | I2: =H2-AVERAGE($H$2:$H$49) | J2: =IF(OR(E2=0,E2=F2),"BIÊN","")
A3: 2 | B3: 208493412207 | C3: Câu 2 MC | D3: MC | E3: =SUM('01_Data'!C2:C1038) | F3: =COUNT('01_Data'!C2:C1038) | G3: =E3/F3 | H3: =LN((F3-E3+0.3)/(E3+0.3)) | I3: =H3-AVERAGE($H$2:$H$49) | J3: =IF(OR(E3=0,E3=F3),"BIÊN","")
A4: 3 | B4: 208493634375 | C4: Câu 3 MC | D4: MC | E4: =SUM('01_Data'!D2:D1038) | F4: =COUNT('01_Data'!D2:D1038) | G4: =E4/F4 | H4: =LN((F4-E4+0.3)/(E4+0.3)) | I4: =H4-AVERAGE($H$2:$H$49) | J4: =IF(OR(E4=0,E4=F4),"BIÊN","")
A5: 4 | B5: 208493806712 | C5: Câu 4 MC | D5: MC | E5: =SUM('01_Data'!E2:E1038) | F5: =COUNT('01_Data'!E2:E1038) | G5: =E5/F5 | H5: =LN((F5-E5+0.3)/(E5+0.3)) | I5: =H5-AVERAGE($H$2:$H$49) | J5: =IF(OR(E5=0,E5=F5),"BIÊN","")
A6: 5 | B6: 208494503646 | C6: Câu 5 MC | D6: MC | E6: =SUM('01_Data'!F2:F1038) | F6: =COUNT('01_Data'!F2:F1038) | G6: =E6/F6 | H6: =LN((F6-E6+0.3)/(E6+0.3)) | I6: =H6-AVERAGE($H$2:$H$49) | J6: =IF(OR(E6=0,E6=F6),"BIÊN","")
A7: 6 | B7: 208495066643 | C7: Câu 6 MC | D7: MC | E7: =SUM('01_Data'!G2:G1038) | F7: =COUNT('01_Data'!G2:G1038) | G7: =E7/F7 | H7: =LN((F7-E7+0.3)/(E7+0.3)) | I7: =H7-AVERAGE($H$2:$H$49) | J7: =IF(OR(E7=0,E7=F7),"BIÊN","")
A8: 7 | B8: 208495459130 | C8: Câu 7 MC | D8: MC | E8: =SUM('01_Data'!H2:H1038) | F8: =COUNT('01_Data'!H2:H1038) | G8: =E8/F8 | H8: =LN((F8-E8+0.3)/(E8+0.3)) | I8: =H8-AVERAGE($H$2:$H$49) | J8: =IF(OR(E8=0,E8=F8),"BIÊN","")
A9: 8 | B9: 208495984573 | C9: Câu 8 MC | D9: MC | E9: =SUM('01_Data'!I2:I1038) | F9: =COUNT('01_Data'!I2:I1038) | G9: =E9/F9 | H9: =LN((F9-E9+0.3)/(E9+0.3)) | I9: =H9-AVERAGE($H$2:$H$49) | J9: =IF(OR(E9=0,E9=F9),"BIÊN","")
A10: 9 | B10: 208496326564 | C10: Câu 9 MC | D10: MC | E10: =SUM('01_Data'!J2:J1038) | F10: =COUNT('01_Data'!J2:J1038) | G10: =E10/F10 | H10: =LN((F10-E10+0.3)/(E10+0.3)) | I10: =H10-AVERAGE($H$2:$H$49) | J10: =IF(OR(E10=0,E10=F10),"BIÊN","")
A11: 10 | B11: 208497043631 | C11: Câu 10 MC | D11: MC | E11: =SUM('01_Data'!K2:K1038) | F11: =COUNT('01_Data'!K2:K1038) | G11: =E11/F11 | H11: =LN((F11-E11+0.3)/(E11+0.3)) | I11: =H11-AVERAGE($H$2:$H$49) | J11: =IF(OR(E11=0,E11=F11),"BIÊN","")
A12: 11 | B12: 208497697530 | C12: Câu 24 MC | D12: MC | E12: =SUM('01_Data'!L2:L1038) | F12: =COUNT('01_Data'!L2:L1038) | G12: =E12/F12 | H12: =LN((F12-E12+0.3)/(E12+0.3)) | I12: =H12-AVERAGE($H$2:$H$49) | J12: =IF(OR(E12=0,E12=F12),"BIÊN","")
A13: 12 | B13: 208497947837 | C13: Câu 23 MC | D13: MC | E13: =SUM('01_Data'!M2:M1038) | F13: =COUNT('01_Data'!M2:M1038) | G13: =E13/F13 | H13: =LN((F13-E13+0.3)/(E13+0.3)) | I13: =H13-AVERAGE($H$2:$H$49) | J13: =IF(OR(E13=0,E13=F13),"BIÊN","")
A14: 13 | B14: 208498680706 | C14: Câu 11 MC | D14: MC | E14: =SUM('01_Data'!N2:N1038) | F14: =COUNT('01_Data'!N2:N1038) | G14: =E14/F14 | H14: =LN((F14-E14+0.3)/(E14+0.3)) | I14: =H14-AVERAGE($H$2:$H$49) | J14: =IF(OR(E14=0,E14=F14),"BIÊN","")
A15: 14 | B15: 208498750254 | C15: Câu 12 MC | D15: MC | E15: =SUM('01_Data'!O2:O1038) | F15: =COUNT('01_Data'!O2:O1038) | G15: =E15/F15 | H15: =LN((F15-E15+0.3)/(E15+0.3)) | I15: =H15-AVERAGE($H$2:$H$49) | J15: =IF(OR(E15=0,E15=F15),"BIÊN","")
A16: 15 | B16: 208500103341 | C16: Câu 13 MC | D16: MC | E16: =SUM('01_Data'!P2:P1038) | F16: =COUNT('01_Data'!P2:P1038) | G16: =E16/F16 | H16: =LN((F16-E16+0.3)/(E16+0.3)) | I16: =H16-AVERAGE($H$2:$H$49) | J16: =IF(OR(E16=0,E16=F16),"BIÊN","")
A17: 16 | B17: 208500538567 | C17: Câu 22 MC | D17: MC | E17: =SUM('01_Data'!Q2:Q1038) | F17: =COUNT('01_Data'!Q2:Q1038) | G17: =E17/F17 | H17: =LN((F17-E17+0.3)/(E17+0.3)) | I17: =H17-AVERAGE($H$2:$H$49) | J17: =IF(OR(E17=0,E17=F17),"BIÊN","")
A18: 17 | B18: 208501397853 | C18: Câu 16 MC | D18: MC | E18: =SUM('01_Data'!R2:R1038) | F18: =COUNT('01_Data'!R2:R1038) | G18: =E18/F18 | H18: =LN((F18-E18+0.3)/(E18+0.3)) | I18: =H18-AVERAGE($H$2:$H$49) | J18: =IF(OR(E18=0,E18=F18),"BIÊN","")
A19: 18 | B19: 208501882621 | C19: Câu 17 MC | D19: MC | E19: =SUM('01_Data'!S2:S1038) | F19: =COUNT('01_Data'!S2:S1038) | G19: =E19/F19 | H19: =LN((F19-E19+0.3)/(E19+0.3)) | I19: =H19-AVERAGE($H$2:$H$49) | J19: =IF(OR(E19=0,E19=F19),"BIÊN","")
A20: 19 | B20: 208502464537 | C20: Câu 18 MC | D20: MC | E20: =SUM('01_Data'!T2:T1038) | F20: =COUNT('01_Data'!T2:T1038) | G20: =E20/F20 | H20: =LN((F20-E20+0.3)/(E20+0.3)) | I20: =H20-AVERAGE($H$2:$H$49) | J20: =IF(OR(E20=0,E20=F20),"BIÊN","")
A21: 20 | B21: 208518915377 | C21: Câu 14 MC | D21: MC | E21: =SUM('01_Data'!U2:U1038) | F21: =COUNT('01_Data'!U2:U1038) | G21: =E21/F21 | H21: =LN((F21-E21+0.3)/(E21+0.3)) | I21: =H21-AVERAGE($H$2:$H$49) | J21: =IF(OR(E21=0,E21=F21),"BIÊN","")
A22: 21 | B22: 208519541200 | C22: Câu 15 MC | D22: MC | E22: =SUM('01_Data'!V2:V1038) | F22: =COUNT('01_Data'!V2:V1038) | G22: =E22/F22 | H22: =LN((F22-E22+0.3)/(E22+0.3)) | I22: =H22-AVERAGE($H$2:$H$49) | J22: =IF(OR(E22=0,E22=F22),"BIÊN","")
A23: 22 | B23: 208519949207 | C23: Câu 19 MC | D23: MC | E23: =SUM('01_Data'!W2:W1038) | F23: =COUNT('01_Data'!W2:W1038) | G23: =E23/F23 | H23: =LN((F23-E23+0.3)/(E23+0.3)) | I23: =H23-AVERAGE($H$2:$H$49) | J23: =IF(OR(E23=0,E23=F23),"BIÊN","")
A24: 23 | B24: 208520832930 | C24: Câu 20 MC | D24: MC | E24: =SUM('01_Data'!X2:X1038) | F24: =COUNT('01_Data'!X2:X1038) | G24: =E24/F24 | H24: =LN((F24-E24+0.3)/(E24+0.3)) | I24: =H24-AVERAGE($H$2:$H$49) | J24: =IF(OR(E24=0,E24=F24),"BIÊN","")
A25: 24 | B25: 208521276474 | C25: Câu 21 MC | D25: MC | E25: =SUM('01_Data'!Y2:Y1038) | F25: =COUNT('01_Data'!Y2:Y1038) | G25: =E25/F25 | H25: =LN((F25-E25+0.3)/(E25+0.3)) | I25: =H25-AVERAGE($H$2:$H$49) | J25: =IF(OR(E25=0,E25=F25),"BIÊN","")
A26: 25 | B26: 208529022568_a | C26: Câu 25.a TF | D26: TF | E26: =SUM('01_Data'!Z2:Z1038) | F26: =COUNT('01_Data'!Z2:Z1038) | G26: =E26/F26 | H26: =LN((F26-E26+0.3)/(E26+0.3)) | I26: =H26-AVERAGE($H$2:$H$49) | J26: =IF(OR(E26=0,E26=F26),"BIÊN","")
A27: 26 | B27: 208529022568_b | C27: Câu 25.b TF | D27: TF | E27: =SUM('01_Data'!AA2:AA1038) | F27: =COUNT('01_Data'!AA2:AA1038) | G27: =E27/F27 | H27: =LN((F27-E27+0.3)/(E27+0.3)) | I27: =H27-AVERAGE($H$2:$H$49) | J27: =IF(OR(E27=0,E27=F27),"BIÊN","")
A28: 27 | B28: 208529022568_c | C28: Câu 25.c TF | D28: TF | E28: =SUM('01_Data'!AB2:AB1038) | F28: =COUNT('01_Data'!AB2:AB1038) | G28: =E28/F28 | H28: =LN((F28-E28+0.3)/(E28+0.3)) | I28: =H28-AVERAGE($H$2:$H$49) | J28: =IF(OR(E28=0,E28=F28),"BIÊN","")
A29: 28 | B29: 208529022568_d | C29: Câu 25.d TF | D29: TF | E29: =SUM('01_Data'!AC2:AC1038) | F29: =COUNT('01_Data'!AC2:AC1038) | G29: =E29/F29 | H29: =LN((F29-E29+0.3)/(E29+0.3)) | I29: =H29-AVERAGE($H$2:$H$49) | J29: =IF(OR(E29=0,E29=F29),"BIÊN","")
A30: 29 | B30: 208560377855_a | C30: Câu 27.a TF | D30: TF | E30: =SUM('01_Data'!AD2:AD1038) | F30: =COUNT('01_Data'!AD2:AD1038) | G30: =E30/F30 | H30: =LN((F30-E30+0.3)/(E30+0.3)) | I30: =H30-AVERAGE($H$2:$H$49) | J30: =IF(OR(E30=0,E30=F30),"BIÊN","")
A31: 30 | B31: 208560377855_b | C31: Câu 27.b TF | D31: TF | E31: =SUM('01_Data'!AE2:AE1038) | F31: =COUNT('01_Data'!AE2:AE1038) | G31: =E31/F31 | H31: =LN((F31-E31+0.3)/(E31+0.3)) | I31: =H31-AVERAGE($H$2:$H$49) | J31: =IF(OR(E31=0,E31=F31),"BIÊN","")
A32: 31 | B32: 208560377855_c | C32: Câu 27.c TF | D32: TF | E32: =SUM('01_Data'!AF2:AF1038) | F32: =COUNT('01_Data'!AF2:AF1038) | G32: =E32/F32 | H32: =LN((F32-E32+0.3)/(E32+0.3)) | I32: =H32-AVERAGE($H$2:$H$49) | J32: =IF(OR(E32=0,E32=F32),"BIÊN","")
A33: 32 | B33: 208560377855_d | C33: Câu 27.d TF | D33: TF | E33: =SUM('01_Data'!AG2:AG1038) | F33: =COUNT('01_Data'!AG2:AG1038) | G33: =E33/F33 | H33: =LN((F33-E33+0.3)/(E33+0.3)) | I33: =H33-AVERAGE($H$2:$H$49) | J33: =IF(OR(E33=0,E33=F33),"BIÊN","")
A34: 33 | B34: 208572448723_a | C34: Câu 26.a TF | D34: TF | E34: =SUM('01_Data'!AH2:AH1038) | F34: =COUNT('01_Data'!AH2:AH1038) | G34: =E34/F34 | H34: =LN((F34-E34+0.3)/(E34+0.3)) | I34: =H34-AVERAGE($H$2:$H$49) | J34: =IF(OR(E34=0,E34=F34),"BIÊN","")
A35: 34 | B35: 208572448723_b | C35: Câu 26.b TF | D35: TF | E35: =SUM('01_Data'!AI2:AI1038) | F35: =COUNT('01_Data'!AI2:AI1038) | G35: =E35/F35 | H35: =LN((F35-E35+0.3)/(E35+0.3)) | I35: =H35-AVERAGE($H$2:$H$49) | J35: =IF(OR(E35=0,E35=F35),"BIÊN","")
A36: 35 | B36: 208572448723_c | C36: Câu 26.c TF | D36: TF | E36: =SUM('01_Data'!AJ2:AJ1038) | F36: =COUNT('01_Data'!AJ2:AJ1038) | G36: =E36/F36 | H36: =LN((F36-E36+0.3)/(E36+0.3)) | I36: =H36-AVERAGE($H$2:$H$49) | J36: =IF(OR(E36=0,E36=F36),"BIÊN","")
A37: 36 | B37: 208572448723_d | C37: Câu 26.d TF | D37: TF | E37: =SUM('01_Data'!AK2:AK1038) | F37: =COUNT('01_Data'!AK2:AK1038) | G37: =E37/F37 | H37: =LN((F37-E37+0.3)/(E37+0.3)) | I37: =H37-AVERAGE($H$2:$H$49) | J37: =IF(OR(E37=0,E37=F37),"BIÊN","")
A38: 37 | B38: 208572588199_a | C38: Câu 28.a TF | D38: TF | E38: =SUM('01_Data'!AL2:AL1038) | F38: =COUNT('01_Data'!AL2:AL1038) | G38: =E38/F38 | H38: =LN((F38-E38+0.3)/(E38+0.3)) | I38: =H38-AVERAGE($H$2:$H$49) | J38: =IF(OR(E38=0,E38=F38),"BIÊN","")
A39: 38 | B39: 208572588199_b | C39: Câu 28.b TF | D39: TF | E39: =SUM('01_Data'!AM2:AM1038) | F39: =COUNT('01_Data'!AM2:AM1038) | G39: =E39/F39 | H39: =LN((F39-E39+0.3)/(E39+0.3)) | I39: =H39-AVERAGE($H$2:$H$49) | J39: =IF(OR(E39=0,E39=F39),"BIÊN","")
A40: 39 | B40: 208572588199_c | C40: Câu 28.c TF | D40: TF | E40: =SUM('01_Data'!AN2:AN1038) | F40: =COUNT('01_Data'!AN2:AN1038) | G40: =E40/F40 | H40: =LN((F40-E40+0.3)/(E40+0.3)) | I40: =H40-AVERAGE($H$2:$H$49) | J40: =IF(OR(E40=0,E40=F40),"BIÊN","")
...

Sheet 03_Lap_Theta
A1: i | B1: iduser | C1: R | D1: M | E1: θ0 | F1: ΣP_1 | G1: ΣP²_1 | H1: θ1 | I1: ΣP_2 | J1: ΣP²_2 | K1: θ2 | L1: ΣP_3 | M1: ΣP²_3 | N1: θ3 | O1: ΣP_4 | P1: ΣP²_4 | Q1: θ4 | R1: ΣP_5 | S1: ΣP²_5 | T1: θ5 | U1: ΣP_6 | V1: ΣP²_6 | W1: θ6 | X1: ΣP_7 | Y1: ΣP²_7 | Z1: θ7 | AA1: ΣP_8 | AB1: ΣP²_8 | AC1: θ8
A2: 1 | B2: ='01_Data'!A2 | C2: =SUM('01_Data'!$B2:$AW2) | D2: =COUNT('01_Data'!$B2:$AW2) | E2: =MEDIAN(-6,LN((C2+0.3)/(D2-C2+0.3)),6) | F2: =SUMPRODUCT(('01_Data'!$B2:$AW2<>"")*(1/(1+EXP(-(E2-'03_Lap_b'!$B$5:$AW$5))))) | G2: =SUMPRODUCT(('01_Data'!$B2:$AW2<>"")*(1/(1+EXP(-(E2-'03_Lap_b'!$B$5:$AW$5))))^2) | H2: =MEDIAN(-6,E2+(C2-F2)/MAX(F2-G2,0.000000001),6) | I2: =SUMPRODUCT(('01_Data'!$B2:$AW2<>"")*(1/(1+EXP(-(H2-'03_Lap_b'!$B$10:$AW$10))))) | J2: =SUMPRODUCT(('01_Data'!$B2:$AW2<>"")*(1/(1+EXP(-(H2-'03_Lap_b'!$B$10:$AW$10))))^2) | K2: =MEDIAN(-6,H2+(C2-I2)/MAX(I2-J2,0.000000001),6) | L2: =SUMPRODUCT(('01_Data'!$B2:$AW2<>"")*(1/(1+EXP(-(K2-'03_Lap_b'!$B$15:$AW$15))))) | M2: =SUMPRODUCT(('01_Data'!$B2:$AW2<>"")*(1/(1+EXP(-(K2-'03_Lap_b'!$B$15:$AW$15))))^2) | N2: =MEDIAN(-6,K2+(C2-L2)/MAX(L2-M2,0.000000001),6) | O2: =SUMPRODUCT(('01_Data'!$B2:$AW2<>"")*(1/(1+EXP(-(N2-'03_Lap_b'!$B$20:$AW$20))))) | P2: =SUMPRODUCT(('01_Data'!$B2:$AW2<>"")*(1/(1+EXP(-(N2-'03_Lap_b'!$B$20:$AW$20))))^2) | Q2: =MEDIAN(-6,N2+(C2-O2)/MAX(O2-P2,0.000000001),6) | R2: =SUMPRODUCT(('01_Data'!$B2:$AW2<>"")*(1/(1+EXP(-(Q2-'03_Lap_b'!$B$25:$AW$25))))) | S2: =SUMPRODUCT(('01_Data'!$B2:$AW2<>"")*(1/(1+EXP(-(Q2-'03_Lap_b'!$B$25:$AW$25))))^2) | T2: =MEDIAN(-6,Q2+(C2-R2)/MAX(R2-S2,0.000000001),6) | U2: =SUMPRODUCT(('01_Data'!$B2:$AW2<>"")*(1/(1+EXP(-(T2-'03_Lap_b'!$B$30:$AW$30))))) | V2: =SUMPRODUCT(('01_Data'!$B2:$AW2<>"")*(1/(1+EXP(-(T2-'03_Lap_b'!$B$30:$AW$30))))^2) | W2: =MEDIAN(-6,T2+(C2-U2)/MAX(U2-V2,0.000000001),6) | X2: =SUMPRODUCT(('01_Data'!$B2:$AW2<>"")*(1/(1+EXP(-(W2-'03_Lap_b'!$B$35:$AW$35))))) | Y2: =SUMPRODUCT(('01_Data'!$B2:$AW2<>"")*(1/(1+EXP(-(W2-'03_Lap_b'!$B$35:$AW$35))))^2) | Z2: =MEDIAN(-6,W2+(C2-X2)/MAX(X2-Y2,0.000000001),6) | AA2: =SUMPRODUCT(('01_Data'!$B2:$AW2<>"")*(1/(1+EXP(-(Z2-'03_Lap_b'!$B$40:$AW$40))))) | AB2: =SUMPRODUCT(('01_Data'!$B2:$AW2<>"")*(1/(1+EXP(-(Z2-'03_Lap_b'!$B$40:$AW$40))))^2) | AC2: =MEDIAN(-6,Z2+(C2-AA2)/MAX(AA2-AB2,0.000000001),6)
A3: 2 | B3: ='01_Data'!A3 | C3: =SUM('01_Data'!$B3:$AW3) | D3: =COUNT('01_Data'!$B3:$AW3) | E3: =MEDIAN(-6,LN((C3+0.3)/(D3-C3+0.3)),6) | F3: =SUMPRODUCT(('01_Data'!$B3:$AW3<>"")*(1/(1+EXP(-(E3-'03_Lap_b'!$B$5:$AW$5))))) | G3: =SUMPRODUCT(('01_Data'!$B3:$AW3<>"")*(1/(1+EXP(-(E3-'03_Lap_b'!$B$5:$AW$5))))^2) | H3: =MEDIAN(-6,E3+(C3-F3)/MAX(F3-G3,0.000000001),6) | I3: =SUMPRODUCT(('01_Data'!$B3:$AW3<>"")*(1/(1+EXP(-(H3-'03_Lap_b'!$B$10:$AW$10))))) | J3: =SUMPRODUCT(('01_Data'!$B3:$AW3<>"")*(1/(1+EXP(-(H3-'03_Lap_b'!$B$10:$AW$10))))^2) | K3: =MEDIAN(-6,H3+(C3-I3)/MAX(I3-J3,0.000000001),6) | L3: =SUMPRODUCT(('01_Data'!$B3:$AW3<>"")*(1/(1+EXP(-(K3-'03_Lap_b'!$B$15:$AW$15))))) | M3: =SUMPRODUCT(('01_Data'!$B3:$AW3<>"")*(1/(1+EXP(-(K3-'03_Lap_b'!$B$15:$AW$15))))^2) | N3: =MEDIAN(-6,K3+(C3-L3)/MAX(L3-M3,0.000000001),6) | O3: =SUMPRODUCT(('01_Data'!$B3:$AW3<>"")*(1/(1+EXP(-(N3-'03_Lap_b'!$B$20:$AW$20))))) | P3: =SUMPRODUCT(('01_Data'!$B3:$AW3<>"")*(1/(1+EXP(-(N3-'03_Lap_b'!$B$20:$AW$20))))^2) | Q3: =MEDIAN(-6,N3+(C3-O3)/MAX(O3-P3,0.000000001),6) | R3: =SUMPRODUCT(('01_Data'!$B3:$AW3<>"")*(1/(1+EXP(-(Q3-'03_Lap_b'!$B$25:$AW$25))))) | S3: =SUMPRODUCT(('01_Data'!$B3:$AW3<>"")*(1/(1+EXP(-(Q3-'03_Lap_b'!$B$25:$AW$25))))^2) | T3: =MEDIAN(-6,Q3+(C3-R3)/MAX(R3-S3,0.000000001),6) | U3: =SUMPRODUCT(('01_Data'!$B3:$AW3<>"")*(1/(1+EXP(-(T3-'03_Lap_b'!$B$30:$AW$30))))) | V3: =SUMPRODUCT(('01_Data'!$B3:$AW3<>"")*(1/(1+EXP(-(T3-'03_Lap_b'!$B$30:$AW$30))))^2) | W3: =MEDIAN(-6,T3+(C3-U3)/MAX(U3-V3,0.000000001),6) | X3: =SUMPRODUCT(('01_Data'!$B3:$AW3<>"")*(1/(1+EXP(-(W3-'03_Lap_b'!$B$35:$AW$35))))) | Y3: =SUMPRODUCT(('01_Data'!$B3:$AW3<>"")*(1/(1+EXP(-(W3-'03_Lap_b'!$B$35:$AW$35))))^2) | Z3: =MEDIAN(-6,W3+(C3-X3)/MAX(X3-Y3,0.000000001),6) | AA3: =SUMPRODUCT(('01_Data'!$B3:$AW3<>"")*(1/(1+EXP(-(Z3-'03_Lap_b'!$B$40:$AW$40))))) | AB3: =SUMPRODUCT(('01_Data'!$B3:$AW3<>"")*(1/(1+EXP(-(Z3-'03_Lap_b'!$B$40:$AW$40))))^2) | AC3: =MEDIAN(-6,Z3+(C3-AA3)/MAX(AA3-AB3,0.000000001),6)
A4: 3 | B4: ='01_Data'!A4 | C4: =SUM('01_Data'!$B4:$AW4) | D4: =COUNT('01_Data'!$B4:$AW4) | E4: =MEDIAN(-6,LN((C4+0.3)/(D4-C4+0.3)),6) | F4: =SUMPRODUCT(('01_Data'!$B4:$AW4<>"")*(1/(1+EXP(-(E4-'03_Lap_b'!$B$5:$AW$5))))) | G4: =SUMPRODUCT(('01_Data'!$B4:$AW4<>"")*(1/(1+EXP(-(E4-'03_Lap_b'!$B$5:$AW$5))))^2) | H4: =MEDIAN(-6,E4+(C4-F4)/MAX(F4-G4,0.000000001),6) | I4: =SUMPRODUCT(('01_Data'!$B4:$AW4<>"")*(1/(1+EXP(-(H4-'03_Lap_b'!$B$10:$AW$10))))) | J4: =SUMPRODUCT(('01_Data'!$B4:$AW4<>"")*(1/(1+EXP(-(H4-'03_Lap_b'!$B$10:$AW$10))))^2) | K4: =MEDIAN(-6,H4+(C4-I4)/MAX(I4-J4,0.000000001),6) | L4: =SUMPRODUCT(('01_Data'!$B4:$AW4<>"")*(1/(1+EXP(-(K4-'03_Lap_b'!$B$15:$AW$15))))) | M4: =SUMPRODUCT(('01_Data'!$B4:$AW4<>"")*(1/(1+EXP(-(K4-'03_Lap_b'!$B$15:$AW$15))))^2) | N4: =MEDIAN(-6,K4+(C4-L4)/MAX(L4-M4,0.000000001),6) | O4: =SUMPRODUCT(('01_Data'!$B4:$AW4<>"")*(1/(1+EXP(-(N4-'03_Lap_b'!$B$20:$AW$20))))) | P4: =SUMPRODUCT(('01_Data'!$B4:$AW4<>"")*(1/(1+EXP(-(N4-'03_Lap_b'!$B$20:$AW$20))))^2) | Q4: =MEDIAN(-6,N4+(C4-O4)/MAX(O4-P4,0.000000001),6) | R4: =SUMPRODUCT(('01_Data'!$B4:$AW4<>"")*(1/(1+EXP(-(Q4-'03_Lap_b'!$B$25:$AW$25))))) | S4: =SUMPRODUCT(('01_Data'!$B4:$AW4<>"")*(1/(1+EXP(-(Q4-'03_Lap_b'!$B$25:$AW$25))))^2) | T4: =MEDIAN(-6,Q4+(C4-R4)/MAX(R4-S4,0.000000001),6) | U4: =SUMPRODUCT(('01_Data'!$B4:$AW4<>"")*(1/(1+EXP(-(T4-'03_Lap_b'!$B$30:$AW$30))))) | V4: =SUMPRODUCT(('01_Data'!$B4:$AW4<>"")*(1/(1+EXP(-(T4-'03_Lap_b'!$B$30:$AW$30))))^2) | W4: =MEDIAN(-6,T4+(C4-U4)/MAX(U4-V4,0.000000001),6) | X4: =SUMPRODUCT(('01_Data'!$B4:$AW4<>"")*(1/(1+EXP(-(W4-'03_Lap_b'!$B$35:$AW$35))))) | Y4: =SUMPRODUCT(('01_Data'!$B4:$AW4<>"")*(1/(1+EXP(-(W4-'03_Lap_b'!$B$35:$AW$35))))^2) | Z4: =MEDIAN(-6,W4+(C4-X4)/MAX(X4-Y4,0.000000001),6) | AA4: =SUMPRODUCT(('01_Data'!$B4:$AW4<>"")*(1/(1+EXP(-(Z4-'03_Lap_b'!$B$40:$AW$40))))) | AB4: =SUMPRODUCT(('01_Data'!$B4:$AW4<>"")*(1/(1+EXP(-(Z4-'03_Lap_b'!$B$40:$AW$40))))^2) | AC4: =MEDIAN(-6,Z4+(C4-AA4)/MAX(AA4-AB4,0.000000001),6)
A5: 4 | B5: ='01_Data'!A5 | C5: =SUM('01_Data'!$B5:$AW5) | D5: =COUNT('01_Data'!$B5:$AW5) | E5: =MEDIAN(-6,LN((C5+0.3)/(D5-C5+0.3)),6) | F5: =SUMPRODUCT(('01_Data'!$B5:$AW5<>"")*(1/(1+EXP(-(E5-'03_Lap_b'!$B$5:$AW$5))))) | G5: =SUMPRODUCT(('01_Data'!$B5:$AW5<>"")*(1/(1+EXP(-(E5-'03_Lap_b'!$B$5:$AW$5))))^2) | H5: =MEDIAN(-6,E5+(C5-F5)/MAX(F5-G5,0.000000001),6) | I5: =SUMPRODUCT(('01_Data'!$B5:$AW5<>"")*(1/(1+EXP(-(H5-'03_Lap_b'!$B$10:$AW$10))))) | J5: =SUMPRODUCT(('01_Data'!$B5:$AW5<>"")*(1/(1+EXP(-(H5-'03_Lap_b'!$B$10:$AW$10))))^2) | K5: =MEDIAN(-6,H5+(C5-I5)/MAX(I5-J5,0.000000001),6) | L5: =SUMPRODUCT(('01_Data'!$B5:$AW5<>"")*(1/(1+EXP(-(K5-'03_Lap_b'!$B$15:$AW$15))))) | M5: =SUMPRODUCT(('01_Data'!$B5:$AW5<>"")*(1/(1+EXP(-(K5-'03_Lap_b'!$B$15:$AW$15))))^2) | N5: =MEDIAN(-6,K5+(C5-L5)/MAX(L5-M5,0.000000001),6) | O5: =SUMPRODUCT(('01_Data'!$B5:$AW5<>"")*(1/(1+EXP(-(N5-'03_Lap_b'!$B$20:$AW$20))))) | P5: =SUMPRODUCT(('01_Data'!$B5:$AW5<>"")*(1/(1+EXP(-(N5-'03_Lap_b'!$B$20:$AW$20))))^2) | Q5: =MEDIAN(-6,N5+(C5-O5)/MAX(O5-P5,0.000000001),6) | R5: =SUMPRODUCT(('01_Data'!$B5:$AW5<>"")*(1/(1+EXP(-(Q5-'03_Lap_b'!$B$25:$AW$25))))) | S5: =SUMPRODUCT(('01_Data'!$B5:$AW5<>"")*(1/(1+EXP(-(Q5-'03_Lap_b'!$B$25:$AW$25))))^2) | T5: =MEDIAN(-6,Q5+(C5-R5)/MAX(R5-S5,0.000000001),6) | U5: =SUMPRODUCT(('01_Data'!$B5:$AW5<>"")*(1/(1+EXP(-(T5-'03_Lap_b'!$B$30:$AW$30))))) | V5: =SUMPRODUCT(('01_Data'!$B5:$AW5<>"")*(1/(1+EXP(-(T5-'03_Lap_b'!$B$30:$AW$30))))^2) | W5: =MEDIAN(-6,T5+(C5-U5)/MAX(U5-V5,0.000000001),6) | X5: =SUMPRODUCT(('01_Data'!$B5:$AW5<>"")*(1/(1+EXP(-(W5-'03_Lap_b'!$B$35:$AW$35))))) | Y5: =SUMPRODUCT(('01_Data'!$B5:$AW5<>"")*(1/(1+EXP(-(W5-'03_Lap_b'!$B$35:$AW$35))))^2) | Z5: =MEDIAN(-6,W5+(C5-X5)/MAX(X5-Y5,0.000000001),6) | AA5: =SUMPRODUCT(('01_Data'!$B5:$AW5<>"")*(1/(1+EXP(-(Z5-'03_Lap_b'!$B$40:$AW$40))))) | AB5: =SUMPRODUCT(('01_Data'!$B5:$AW5<>"")*(1/(1+EXP(-(Z5-'03_Lap_b'!$B$40:$AW$40))))^2) | AC5: =MEDIAN(-6,Z5+(C5-AA5)/MAX(AA5-AB5,0.000000001),6)
A6: 5 | B6: ='01_Data'!A6 | C6: =SUM('01_Data'!$B6:$AW6) | D6: =COUNT('01_Data'!$B6:$AW6) | E6: =MEDIAN(-6,LN((C6+0.3)/(D6-C6+0.3)),6) | F6: =SUMPRODUCT(('01_Data'!$B6:$AW6<>"")*(1/(1+EXP(-(E6-'03_Lap_b'!$B$5:$AW$5))))) | G6: =SUMPRODUCT(('01_Data'!$B6:$AW6<>"")*(1/(1+EXP(-(E6-'03_Lap_b'!$B$5:$AW$5))))^2) | H6: =MEDIAN(-6,E6+(C6-F6)/MAX(F6-G6,0.000000001),6) | I6: =SUMPRODUCT(('01_Data'!$B6:$AW6<>"")*(1/(1+EXP(-(H6-'03_Lap_b'!$B$10:$AW$10))))) | J6: =SUMPRODUCT(('01_Data'!$B6:$AW6<>"")*(1/(1+EXP(-(H6-'03_Lap_b'!$B$10:$AW$10))))^2) | K6: =MEDIAN(-6,H6+(C6-I6)/MAX(I6-J6,0.000000001),6) | L6: =SUMPRODUCT(('01_Data'!$B6:$AW6<>"")*(1/(1+EXP(-(K6-'03_Lap_b'!$B$15:$AW$15))))) | M6: =SUMPRODUCT(('01_Data'!$B6:$AW6<>"")*(1/(1+EXP(-(K6-'03_Lap_b'!$B$15:$AW$15))))^2) | N6: =MEDIAN(-6,K6+(C6-L6)/MAX(L6-M6,0.000000001),6) | O6: =SUMPRODUCT(('01_Data'!$B6:$AW6<>"")*(1/(1+EXP(-(N6-'03_Lap_b'!$B$20:$AW$20))))) | P6: =SUMPRODUCT(('01_Data'!$B6:$AW6<>"")*(1/(1+EXP(-(N6-'03_Lap_b'!$B$20:$AW$20))))^2) | Q6: =MEDIAN(-6,N6+(C6-O6)/MAX(O6-P6,0.000000001),6) | R6: =SUMPRODUCT(('01_Data'!$B6:$AW6<>"")*(1/(1+EXP(-(Q6-'03_Lap_b'!$B$25:$AW$25))))) | S6: =SUMPRODUCT(('01_Data'!$B6:$AW6<>"")*(1/(1+EXP(-(Q6-'03_Lap_b'!$B$25:$AW$25))))^2) | T6: =MEDIAN(-6,Q6+(C6-R6)/MAX(R6-S6,0.000000001),6) | U6: =SUMPRODUCT(('01_Data'!$B6:$AW6<>"")*(1/(1+EXP(-(T6-'03_Lap_b'!$B$30:$AW$30))))) | V6: =SUMPRODUCT(('01_Data'!$B6:$AW6<>"")*(1/(1+EXP(-(T6-'03_Lap_b'!$B$30:$AW$30))))^2) | W6: =MEDIAN(-6,T6+(C6-U6)/MAX(U6-V6,0.000000001),6) | X6: =SUMPRODUCT(('01_Data'!$B6:$AW6<>"")*(1/(1+EXP(-(W6-'03_Lap_b'!$B$35:$AW$35))))) | Y6: =SUMPRODUCT(('01_Data'!$B6:$AW6<>"")*(1/(1+EXP(-(W6-'03_Lap_b'!$B$35:$AW$35))))^2) | Z6: =MEDIAN(-6,W6+(C6-X6)/MAX(X6-Y6,0.000000001),6) | AA6: =SUMPRODUCT(('01_Data'!$B6:$AW6<>"")*(1/(1+EXP(-(Z6-'03_Lap_b'!$B$40:$AW$40))))) | AB6: =SUMPRODUCT(('01_Data'!$B6:$AW6<>"")*(1/(1+EXP(-(Z6-'03_Lap_b'!$B$40:$AW$40))))^2) | AC6: =MEDIAN(-6,Z6+(C6-AA6)/MAX(AA6-AB6,0.000000001),6)
A7: 6 | B7: ='01_Data'!A7 | C7: =SUM('01_Data'!$B7:$AW7) | D7: =COUNT('01_Data'!$B7:$AW7) | E7: =MEDIAN(-6,LN((C7+0.3)/(D7-C7+0.3)),6) | F7: =SUMPRODUCT(('01_Data'!$B7:$AW7<>"")*(1/(1+EXP(-(E7-'03_Lap_b'!$B$5:$AW$5))))) | G7: =SUMPRODUCT(('01_Data'!$B7:$AW7<>"")*(1/(1+EXP(-(E7-'03_Lap_b'!$B$5:$AW$5))))^2) | H7: =MEDIAN(-6,E7+(C7-F7)/MAX(F7-G7,0.000000001),6) | I7: =SUMPRODUCT(('01_Data'!$B7:$AW7<>"")*(1/(1+EXP(-(H7-'03_Lap_b'!$B$10:$AW$10))))) | J7: =SUMPRODUCT(('01_Data'!$B7:$AW7<>"")*(1/(1+EXP(-(H7-'03_Lap_b'!$B$10:$AW$10))))^2) | K7: =MEDIAN(-6,H7+(C7-I7)/MAX(I7-J7,0.000000001),6) | L7: =SUMPRODUCT(('01_Data'!$B7:$AW7<>"")*(1/(1+EXP(-(K7-'03_Lap_b'!$B$15:$AW$15))))) | M7: =SUMPRODUCT(('01_Data'!$B7:$AW7<>"")*(1/(1+EXP(-(K7-'03_Lap_b'!$B$15:$AW$15))))^2) | N7: =MEDIAN(-6,K7+(C7-L7)/MAX(L7-M7,0.000000001),6) | O7: =SUMPRODUCT(('01_Data'!$B7:$AW7<>"")*(1/(1+EXP(-(N7-'03_Lap_b'!$B$20:$AW$20))))) | P7: =SUMPRODUCT(('01_Data'!$B7:$AW7<>"")*(1/(1+EXP(-(N7-'03_Lap_b'!$B$20:$AW$20))))^2) | Q7: =MEDIAN(-6,N7+(C7-O7)/MAX(O7-P7,0.000000001),6) | R7: =SUMPRODUCT(('01_Data'!$B7:$AW7<>"")*(1/(1+EXP(-(Q7-'03_Lap_b'!$B$25:$AW$25))))) | S7: =SUMPRODUCT(('01_Data'!$B7:$AW7<>"")*(1/(1+EXP(-(Q7-'03_Lap_b'!$B$25:$AW$25))))^2) | T7: =MEDIAN(-6,Q7+(C7-R7)/MAX(R7-S7,0.000000001),6) | U7: =SUMPRODUCT(('01_Data'!$B7:$AW7<>"")*(1/(1+EXP(-(T7-'03_Lap_b'!$B$30:$AW$30))))) | V7: =SUMPRODUCT(('01_Data'!$B7:$AW7<>"")*(1/(1+EXP(-(T7-'03_Lap_b'!$B$30:$AW$30))))^2) | W7: =MEDIAN(-6,T7+(C7-U7)/MAX(U7-V7,0.000000001),6) | X7: =SUMPRODUCT(('01_Data'!$B7:$AW7<>"")*(1/(1+EXP(-(W7-'03_Lap_b'!$B$35:$AW$35))))) | Y7: =SUMPRODUCT(('01_Data'!$B7:$AW7<>"")*(1/(1+EXP(-(W7-'03_Lap_b'!$B$35:$AW$35))))^2) | Z7: =MEDIAN(-6,W7+(C7-X7)/MAX(X7-Y7,0.000000001),6) | AA7: =SUMPRODUCT(('01_Data'!$B7:$AW7<>"")*(1/(1+EXP(-(Z7-'03_Lap_b'!$B$40:$AW$40))))) | AB7: =SUMPRODUCT(('01_Data'!$B7:$AW7<>"")*(1/(1+EXP(-(Z7-'03_Lap_b'!$B$40:$AW$40))))^2) | AC7: =MEDIAN(-6,Z7+(C7-AA7)/MAX(AA7-AB7,0.000000001),6)
A8: 7 | B8: ='01_Data'!A8 | C8: =SUM('01_Data'!$B8:$AW8) | D8: =COUNT('01_Data'!$B8:$AW8) | E8: =MEDIAN(-6,LN((C8+0.3)/(D8-C8+0.3)),6) | F8: =SUMPRODUCT(('01_Data'!$B8:$AW8<>"")*(1/(1+EXP(-(E8-'03_Lap_b'!$B$5:$AW$5))))) | G8: =SUMPRODUCT(('01_Data'!$B8:$AW8<>"")*(1/(1+EXP(-(E8-'03_Lap_b'!$B$5:$AW$5))))^2) | H8: =MEDIAN(-6,E8+(C8-F8)/MAX(F8-G8,0.000000001),6) | I8: =SUMPRODUCT(('01_Data'!$B8:$AW8<>"")*(1/(1+EXP(-(H8-'03_Lap_b'!$B$10:$AW$10))))) | J8: =SUMPRODUCT(('01_Data'!$B8:$AW8<>"")*(1/(1+EXP(-(H8-'03_Lap_b'!$B$10:$AW$10))))^2) | K8: =MEDIAN(-6,H8+(C8-I8)/MAX(I8-J8,0.000000001),6) | L8: =SUMPRODUCT(('01_Data'!$B8:$AW8<>"")*(1/(1+EXP(-(K8-'03_Lap_b'!$B$15:$AW$15))))) | M8: =SUMPRODUCT(('01_Data'!$B8:$AW8<>"")*(1/(1+EXP(-(K8-'03_Lap_b'!$B$15:$AW$15))))^2) | N8: =MEDIAN(-6,K8+(C8-L8)/MAX(L8-M8,0.000000001),6) | O8: =SUMPRODUCT(('01_Data'!$B8:$AW8<>"")*(1/(1+EXP(-(N8-'03_Lap_b'!$B$20:$AW$20))))) | P8: =SUMPRODUCT(('01_Data'!$B8:$AW8<>"")*(1/(1+EXP(-(N8-'03_Lap_b'!$B$20:$AW$20))))^2) | Q8: =MEDIAN(-6,N8+(C8-O8)/MAX(O8-P8,0.000000001),6) | R8: =SUMPRODUCT(('01_Data'!$B8:$AW8<>"")*(1/(1+EXP(-(Q8-'03_Lap_b'!$B$25:$AW$25))))) | S8: =SUMPRODUCT(('01_Data'!$B8:$AW8<>"")*(1/(1+EXP(-(Q8-'03_Lap_b'!$B$25:$AW$25))))^2) | T8: =MEDIAN(-6,Q8+(C8-R8)/MAX(R8-S8,0.000000001),6) | U8: =SUMPRODUCT(('01_Data'!$B8:$AW8<>"")*(1/(1+EXP(-(T8-'03_Lap_b'!$B$30:$AW$30))))) | V8: =SUMPRODUCT(('01_Data'!$B8:$AW8<>"")*(1/(1+EXP(-(T8-'03_Lap_b'!$B$30:$AW$30))))^2) | W8: =MEDIAN(-6,T8+(C8-U8)/MAX(U8-V8,0.000000001),6) | X8: =SUMPRODUCT(('01_Data'!$B8:$AW8<>"")*(1/(1+EXP(-(W8-'03_Lap_b'!$B$35:$AW$35))))) | Y8: =SUMPRODUCT(('01_Data'!$B8:$AW8<>"")*(1/(1+EXP(-(W8-'03_Lap_b'!$B$35:$AW$35))))^2) | Z8: =MEDIAN(-6,W8+(C8-X8)/MAX(X8-Y8,0.000000001),6) | AA8: =SUMPRODUCT(('01_Data'!$B8:$AW8<>"")*(1/(1+EXP(-(Z8-'03_Lap_b'!$B$40:$AW$40))))) | AB8: =SUMPRODUCT(('01_Data'!$B8:$AW8<>"")*(1/(1+EXP(-(Z8-'03_Lap_b'!$B$40:$AW$40))))^2) | AC8: =MEDIAN(-6,Z8+(C8-AA8)/MAX(AA8-AB8,0.000000001),6)
A9: 8 | B9: ='01_Data'!A9 | C9: =SUM('01_Data'!$B9:$AW9) | D9: =COUNT('01_Data'!$B9:$AW9) | E9: =MEDIAN(-6,LN((C9+0.3)/(D9-C9+0.3)),6) | F9: =SUMPRODUCT(('01_Data'!$B9:$AW9<>"")*(1/(1+EXP(-(E9-'03_Lap_b'!$B$5:$AW$5))))) | G9: =SUMPRODUCT(('01_Data'!$B9:$AW9<>"")*(1/(1+EXP(-(E9-'03_Lap_b'!$B$5:$AW$5))))^2) | H9: =MEDIAN(-6,E9+(C9-F9)/MAX(F9-G9,0.000000001),6) | I9: =SUMPRODUCT(('01_Data'!$B9:$AW9<>"")*(1/(1+EXP(-(H9-'03_Lap_b'!$B$10:$AW$10))))) | J9: =SUMPRODUCT(('01_Data'!$B9:$AW9<>"")*(1/(1+EXP(-(H9-'03_Lap_b'!$B$10:$AW$10))))^2) | K9: =MEDIAN(-6,H9+(C9-I9)/MAX(I9-J9,0.000000001),6) | L9: =SUMPRODUCT(('01_Data'!$B9:$AW9<>"")*(1/(1+EXP(-(K9-'03_Lap_b'!$B$15:$AW$15))))) | M9: =SUMPRODUCT(('01_Data'!$B9:$AW9<>"")*(1/(1+EXP(-(K9-'03_Lap_b'!$B$15:$AW$15))))^2) | N9: =MEDIAN(-6,K9+(C9-L9)/MAX(L9-M9,0.000000001),6) | O9: =SUMPRODUCT(('01_Data'!$B9:$AW9<>"")*(1/(1+EXP(-(N9-'03_Lap_b'!$B$20:$AW$20))))) | P9: =SUMPRODUCT(('01_Data'!$B9:$AW9<>"")*(1/(1+EXP(-(N9-'03_Lap_b'!$B$20:$AW$20))))^2) | Q9: =MEDIAN(-6,N9+(C9-O9)/MAX(O9-P9,0.000000001),6) | R9: =SUMPRODUCT(('01_Data'!$B9:$AW9<>"")*(1/(1+EXP(-(Q9-'03_Lap_b'!$B$25:$AW$25))))) | S9: =SUMPRODUCT(('01_Data'!$B9:$AW9<>"")*(1/(1+EXP(-(Q9-'03_Lap_b'!$B$25:$AW$25))))^2) | T9: =MEDIAN(-6,Q9+(C9-R9)/MAX(R9-S9,0.000000001),6) | U9: =SUMPRODUCT(('01_Data'!$B9:$AW9<>"")*(1/(1+EXP(-(T9-'03_Lap_b'!$B$30:$AW$30))))) | V9: =SUMPRODUCT(('01_Data'!$B9:$AW9<>"")*(1/(1+EXP(-(T9-'03_Lap_b'!$B$30:$AW$30))))^2) | W9: =MEDIAN(-6,T9+(C9-U9)/MAX(U9-V9,0.000000001),6) | X9: =SUMPRODUCT(('01_Data'!$B9:$AW9<>"")*(1/(1+EXP(-(W9-'03_Lap_b'!$B$35:$AW$35))))) | Y9: =SUMPRODUCT(('01_Data'!$B9:$AW9<>"")*(1/(1+EXP(-(W9-'03_Lap_b'!$B$35:$AW$35))))^2) | Z9: =MEDIAN(-6,W9+(C9-X9)/MAX(X9-Y9,0.000000001),6) | AA9: =SUMPRODUCT(('01_Data'!$B9:$AW9<>"")*(1/(1+EXP(-(Z9-'03_Lap_b'!$B$40:$AW$40))))) | AB9: =SUMPRODUCT(('01_Data'!$B9:$AW9<>"")*(1/(1+EXP(-(Z9-'03_Lap_b'!$B$40:$AW$40))))^2) | AC9: =MEDIAN(-6,Z9+(C9-AA9)/MAX(AA9-AB9,0.000000001),6)
A10: 9 | B10: ='01_Data'!A10 | C10: =SUM('01_Data'!$B10:$AW10) | D10: =COUNT('01_Data'!$B10:$AW10) | E10: =MEDIAN(-6,LN((C10+0.3)/(D10-C10+0.3)),6) | F10: =SUMPRODUCT(('01_Data'!$B10:$AW10<>"")*(1/(1+EXP(-(E10-'03_Lap_b'!$B$5:$AW$5))))) | G10: =SUMPRODUCT(('01_Data'!$B10:$AW10<>"")*(1/(1+EXP(-(E10-'03_Lap_b'!$B$5:$AW$5))))^2) | H10: =MEDIAN(-6,E10+(C10-F10)/MAX(F10-G10,0.000000001),6) | I10: =SUMPRODUCT(('01_Data'!$B10:$AW10<>"")*(1/(1+EXP(-(H10-'03_Lap_b'!$B$10:$AW$10))))) | J10: =SUMPRODUCT(('01_Data'!$B10:$AW10<>"")*(1/(1+EXP(-(H10-'03_Lap_b'!$B$10:$AW$10))))^2) | K10: =MEDIAN(-6,H10+(C10-I10)/MAX(I10-J10,0.000000001),6) | L10: =SUMPRODUCT(('01_Data'!$B10:$AW10<>"")*(1/(1+EXP(-(K10-'03_Lap_b'!$B$15:$AW$15))))) | M10: =SUMPRODUCT(('01_Data'!$B10:$AW10<>"")*(1/(1+EXP(-(K10-'03_Lap_b'!$B$15:$AW$15))))^2) | N10: =MEDIAN(-6,K10+(C10-L10)/MAX(L10-M10,0.000000001),6) | O10: =SUMPRODUCT(('01_Data'!$B10:$AW10<>"")*(1/(1+EXP(-(N10-'03_Lap_b'!$B$20:$AW$20))))) | P10: =SUMPRODUCT(('01_Data'!$B10:$AW10<>"")*(1/(1+EXP(-(N10-'03_Lap_b'!$B$20:$AW$20))))^2) | Q10: =MEDIAN(-6,N10+(C10-O10)/MAX(O10-P10,0.000000001),6) | R10: =SUMPRODUCT(('01_Data'!$B10:$AW10<>"")*(1/(1+EXP(-(Q10-'03_Lap_b'!$B$25:$AW$25))))) | S10: =SUMPRODUCT(('01_Data'!$B10:$AW10<>"")*(1/(1+EXP(-(Q10-'03_Lap_b'!$B$25:$AW$25))))^2) | T10: =MEDIAN(-6,Q10+(C10-R10)/MAX(R10-S10,0.000000001),6) | U10: =SUMPRODUCT(('01_Data'!$B10:$AW10<>"")*(1/(1+EXP(-(T10-'03_Lap_b'!$B$30:$AW$30))))) | V10: =SUMPRODUCT(('01_Data'!$B10:$AW10<>"")*(1/(1+EXP(-(T10-'03_Lap_b'!$B$30:$AW$30))))^2) | W10: =MEDIAN(-6,T10+(C10-U10)/MAX(U10-V10,0.000000001),6) | X10: =SUMPRODUCT(('01_Data'!$B10:$AW10<>"")*(1/(1+EXP(-(W10-'03_Lap_b'!$B$35:$AW$35))))) | Y10: =SUMPRODUCT(('01_Data'!$B10:$AW10<>"")*(1/(1+EXP(-(W10-'03_Lap_b'!$B$35:$AW$35))))^2) | Z10: =MEDIAN(-6,W10+(C10-X10)/MAX(X10-Y10,0.000000001),6) | AA10: =SUMPRODUCT(('01_Data'!$B10:$AW10<>"")*(1/(1+EXP(-(Z10-'03_Lap_b'!$B$40:$AW$40))))) | AB10: =SUMPRODUCT(('01_Data'!$B10:$AW10<>"")*(1/(1+EXP(-(Z10-'03_Lap_b'!$B$40:$AW$40))))^2) | AC10: =MEDIAN(-6,Z10+(C10-AA10)/MAX(AA10-AB10,0.000000001),6)
A11: 10 | B11: ='01_Data'!A11 | C11: =SUM('01_Data'!$B11:$AW11) | D11: =COUNT('01_Data'!$B11:$AW11) | E11: =MEDIAN(-6,LN((C11+0.3)/(D11-C11+0.3)),6) | F11: =SUMPRODUCT(('01_Data'!$B11:$AW11<>"")*(1/(1+EXP(-(E11-'03_Lap_b'!$B$5:$AW$5))))) | G11: =SUMPRODUCT(('01_Data'!$B11:$AW11<>"")*(1/(1+EXP(-(E11-'03_Lap_b'!$B$5:$AW$5))))^2) | H11: =MEDIAN(-6,E11+(C11-F11)/MAX(F11-G11,0.000000001),6) | I11: =SUMPRODUCT(('01_Data'!$B11:$AW11<>"")*(1/(1+EXP(-(H11-'03_Lap_b'!$B$10:$AW$10))))) | J11: =SUMPRODUCT(('01_Data'!$B11:$AW11<>"")*(1/(1+EXP(-(H11-'03_Lap_b'!$B$10:$AW$10))))^2) | K11: =MEDIAN(-6,H11+(C11-I11)/MAX(I11-J11,0.000000001),6) | L11: =SUMPRODUCT(('01_Data'!$B11:$AW11<>"")*(1/(1+EXP(-(K11-'03_Lap_b'!$B$15:$AW$15))))) | M11: =SUMPRODUCT(('01_Data'!$B11:$AW11<>"")*(1/(1+EXP(-(K11-'03_Lap_b'!$B$15:$AW$15))))^2) | N11: =MEDIAN(-6,K11+(C11-L11)/MAX(L11-M11,0.000000001),6) | O11: =SUMPRODUCT(('01_Data'!$B11:$AW11<>"")*(1/(1+EXP(-(N11-'03_Lap_b'!$B$20:$AW$20))))) | P11: =SUMPRODUCT(('01_Data'!$B11:$AW11<>"")*(1/(1+EXP(-(N11-'03_Lap_b'!$B$20:$AW$20))))^2) | Q11: =MEDIAN(-6,N11+(C11-O11)/MAX(O11-P11,0.000000001),6) | R11: =SUMPRODUCT(('01_Data'!$B11:$AW11<>"")*(1/(1+EXP(-(Q11-'03_Lap_b'!$B$25:$AW$25))))) | S11: =SUMPRODUCT(('01_Data'!$B11:$AW11<>"")*(1/(1+EXP(-(Q11-'03_Lap_b'!$B$25:$AW$25))))^2) | T11: =MEDIAN(-6,Q11+(C11-R11)/MAX(R11-S11,0.000000001),6) | U11: =SUMPRODUCT(('01_Data'!$B11:$AW11<>"")*(1/(1+EXP(-(T11-'03_Lap_b'!$B$30:$AW$30))))) | V11: =SUMPRODUCT(('01_Data'!$B11:$AW11<>"")*(1/(1+EXP(-(T11-'03_Lap_b'!$B$30:$AW$30))))^2) | W11: =MEDIAN(-6,T11+(C11-U11)/MAX(U11-V11,0.000000001),6) | X11: =SUMPRODUCT(('01_Data'!$B11:$AW11<>"")*(1/(1+EXP(-(W11-'03_Lap_b'!$B$35:$AW$35))))) | Y11: =SUMPRODUCT(('01_Data'!$B11:$AW11<>"")*(1/(1+EXP(-(W11-'03_Lap_b'!$B$35:$AW$35))))^2) | Z11: =MEDIAN(-6,W11+(C11-X11)/MAX(X11-Y11,0.000000001),6) | AA11: =SUMPRODUCT(('01_Data'!$B11:$AW11<>"")*(1/(1+EXP(-(Z11-'03_Lap_b'!$B$40:$AW$40))))) | AB11: =SUMPRODUCT(('01_Data'!$B11:$AW11<>"")*(1/(1+EXP(-(Z11-'03_Lap_b'!$B$40:$AW$40))))^2) | AC11: =MEDIAN(-6,Z11+(C11-AA11)/MAX(AA11-AB11,0.000000001),6)
A12: 11 | B12: ='01_Data'!A12 | C12: =SUM('01_Data'!$B12:$AW12) | D12: =COUNT('01_Data'!$B12:$AW12) | E12: =MEDIAN(-6,LN((C12+0.3)/(D12-C12+0.3)),6) | F12: =SUMPRODUCT(('01_Data'!$B12:$AW12<>"")*(1/(1+EXP(-(E12-'03_Lap_b'!$B$5:$AW$5))))) | G12: =SUMPRODUCT(('01_Data'!$B12:$AW12<>"")*(1/(1+EXP(-(E12-'03_Lap_b'!$B$5:$AW$5))))^2) | H12: =MEDIAN(-6,E12+(C12-F12)/MAX(F12-G12,0.000000001),6) | I12: =SUMPRODUCT(('01_Data'!$B12:$AW12<>"")*(1/(1+EXP(-(H12-'03_Lap_b'!$B$10:$AW$10))))) | J12: =SUMPRODUCT(('01_Data'!$B12:$AW12<>"")*(1/(1+EXP(-(H12-'03_Lap_b'!$B$10:$AW$10))))^2) | K12: =MEDIAN(-6,H12+(C12-I12)/MAX(I12-J12,0.000000001),6) | L12: =SUMPRODUCT(('01_Data'!$B12:$AW12<>"")*(1/(1+EXP(-(K12-'03_Lap_b'!$B$15:$AW$15))))) | M12: =SUMPRODUCT(('01_Data'!$B12:$AW12<>"")*(1/(1+EXP(-(K12-'03_Lap_b'!$B$15:$AW$15))))^2) | N12: =MEDIAN(-6,K12+(C12-L12)/MAX(L12-M12,0.000000001),6) | O12: =SUMPRODUCT(('01_Data'!$B12:$AW12<>"")*(1/(1+EXP(-(N12-'03_Lap_b'!$B$20:$AW$20))))) | P12: =SUMPRODUCT(('01_Data'!$B12:$AW12<>"")*(1/(1+EXP(-(N12-'03_Lap_b'!$B$20:$AW$20))))^2) | Q12: =MEDIAN(-6,N12+(C12-O12)/MAX(O12-P12,0.000000001),6) | R12: =SUMPRODUCT(('01_Data'!$B12:$AW12<>"")*(1/(1+EXP(-(Q12-'03_Lap_b'!$B$25:$AW$25))))) | S12: =SUMPRODUCT(('01_Data'!$B12:$AW12<>"")*(1/(1+EXP(-(Q12-'03_Lap_b'!$B$25:$AW$25))))^2) | T12: =MEDIAN(-6,Q12+(C12-R12)/MAX(R12-S12,0.000000001),6) | U12: =SUMPRODUCT(('01_Data'!$B12:$AW12<>"")*(1/(1+EXP(-(T12-'03_Lap_b'!$B$30:$AW$30))))) | V12: =SUMPRODUCT(('01_Data'!$B12:$AW12<>"")*(1/(1+EXP(-(T12-'03_Lap_b'!$B$30:$AW$30))))^2) | W12: =MEDIAN(-6,T12+(C12-U12)/MAX(U12-V12,0.000000001),6) | X12: =SUMPRODUCT(('01_Data'!$B12:$AW12<>"")*(1/(1+EXP(-(W12-'03_Lap_b'!$B$35:$AW$35))))) | Y12: =SUMPRODUCT(('01_Data'!$B12:$AW12<>"")*(1/(1+EXP(-(W12-'03_Lap_b'!$B$35:$AW$35))))^2) | Z12: =MEDIAN(-6,W12+(C12-X12)/MAX(X12-Y12,0.000000001),6) | AA12: =SUMPRODUCT(('01_Data'!$B12:$AW12<>"")*(1/(1+EXP(-(Z12-'03_Lap_b'!$B$40:$AW$40))))) | AB12: =SUMPRODUCT(('01_Data'!$B12:$AW12<>"")*(1/(1+EXP(-(Z12-'03_Lap_b'!$B$40:$AW$40))))^2) | AC12: =MEDIAN(-6,Z12+(C12-AA12)/MAX(AA12-AB12,0.000000001),6)
A13: 12 | B13: ='01_Data'!A13 | C13: =SUM('01_Data'!$B13:$AW13) | D13: =COUNT('01_Data'!$B13:$AW13) | E13: =MEDIAN(-6,LN((C13+0.3)/(D13-C13+0.3)),6) | F13: =SUMPRODUCT(('01_Data'!$B13:$AW13<>"")*(1/(1+EXP(-(E13-'03_Lap_b'!$B$5:$AW$5))))) | G13: =SUMPRODUCT(('01_Data'!$B13:$AW13<>"")*(1/(1+EXP(-(E13-'03_Lap_b'!$B$5:$AW$5))))^2) | H13: =MEDIAN(-6,E13+(C13-F13)/MAX(F13-G13,0.000000001),6) | I13: =SUMPRODUCT(('01_Data'!$B13:$AW13<>"")*(1/(1+EXP(-(H13-'03_Lap_b'!$B$10:$AW$10))))) | J13: =SUMPRODUCT(('01_Data'!$B13:$AW13<>"")*(1/(1+EXP(-(H13-'03_Lap_b'!$B$10:$AW$10))))^2) | K13: =MEDIAN(-6,H13+(C13-I13)/MAX(I13-J13,0.000000001),6) | L13: =SUMPRODUCT(('01_Data'!$B13:$AW13<>"")*(1/(1+EXP(-(K13-'03_Lap_b'!$B$15:$AW$15))))) | M13: =SUMPRODUCT(('01_Data'!$B13:$AW13<>"")*(1/(1+EXP(-(K13-'03_Lap_b'!$B$15:$AW$15))))^2) | N13: =MEDIAN(-6,K13+(C13-L13)/MAX(L13-M13,0.000000001),6) | O13: =SUMPRODUCT(('01_Data'!$B13:$AW13<>"")*(1/(1+EXP(-(N13-'03_Lap_b'!$B$20:$AW$20))))) | P13: =SUMPRODUCT(('01_Data'!$B13:$AW13<>"")*(1/(1+EXP(-(N13-'03_Lap_b'!$B$20:$AW$20))))^2) | Q13: =MEDIAN(-6,N13+(C13-O13)/MAX(O13-P13,0.000000001),6) | R13: =SUMPRODUCT(('01_Data'!$B13:$AW13<>"")*(1/(1+EXP(-(Q13-'03_Lap_b'!$B$25:$AW$25))))) | S13: =SUMPRODUCT(('01_Data'!$B13:$AW13<>"")*(1/(1+EXP(-(Q13-'03_Lap_b'!$B$25:$AW$25))))^2) | T13: =MEDIAN(-6,Q13+(C13-R13)/MAX(R13-S13,0.000000001),6) | U13: =SUMPRODUCT(('01_Data'!$B13:$AW13<>"")*(1/(1+EXP(-(T13-'03_Lap_b'!$B$30:$AW$30))))) | V13: =SUMPRODUCT(('01_Data'!$B13:$AW13<>"")*(1/(1+EXP(-(T13-'03_Lap_b'!$B$30:$AW$30))))^2) | W13: =MEDIAN(-6,T13+(C13-U13)/MAX(U13-V13,0.000000001),6) | X13: =SUMPRODUCT(('01_Data'!$B13:$AW13<>"")*(1/(1+EXP(-(W13-'03_Lap_b'!$B$35:$AW$35))))) | Y13: =SUMPRODUCT(('01_Data'!$B13:$AW13<>"")*(1/(1+EXP(-(W13-'03_Lap_b'!$B$35:$AW$35))))^2) | Z13: =MEDIAN(-6,W13+(C13-X13)/MAX(X13-Y13,0.000000001),6) | AA13: =SUMPRODUCT(('01_Data'!$B13:$AW13<>"")*(1/(1+EXP(-(Z13-'03_Lap_b'!$B$40:$AW$40))))) | AB13: =SUMPRODUCT(('01_Data'!$B13:$AW13<>"")*(1/(1+EXP(-(Z13-'03_Lap_b'!$B$40:$AW$40))))^2) | AC13: =MEDIAN(-6,Z13+(C13-AA13)/MAX(AA13-AB13,0.000000001),6)
... A1038: 1037 | B1038: ='01_Data'!A1038 | C1038: =SUM('01_Data'!$B1038:$AW1038) | D1038: =COUNT('01_Data'!$B1038:$AW1038) | E1038: =MEDIAN(-6,LN((C1038+0.3)/(D1038-C1038+0.3)),6) | F1038: =SUMPRODUCT(('01_Data'!$B1038:$AW1038<>"")*(1/(1+EXP(-(E1038-'03_Lap_b'!$B$5:$AW$5))))) | G1038: =SUMPRODUCT(('01_Data'!$B1038:$AW1038<>"")*(1/(1+EXP(-(E1038-'03_Lap_b'!$B$5:$AW$5))))^2) | H1038: =MEDIAN(-6,E1038+(C1038-F1038)/MAX(F1038-G1038,0.000000001),6) | I1038: =SUMPRODUCT(('01_Data'!$B1038:$AW1038<>"")*(1/(1+EXP(-(H1038-'03_Lap_b'!$B$10:$AW$10))))) | J1038: =SUMPRODUCT(('01_Data'!$B1038:$AW1038<>"")*(1/(1+EXP(-(H1038-'03_Lap_b'!$B$10:$AW$10))))^2) | K1038: =MEDIAN(-6,H1038+(C1038-I1038)/MAX(I1038-J1038,0.000000001),6) | L1038: =SUMPRODUCT(('01_Data'!$B1038:$AW1038<>"")*(1/(1+EXP(-(K1038-'03_Lap_b'!$B$15:$AW$15))))) | M1038: =SUMPRODUCT(('01_Data'!$B1038:$AW1038<>"")*(1/(1+EXP(-(K1038-'03_Lap_b'!$B$15:$AW$15))))^2) | N1038: =MEDIAN(-6,K1038+(C1038-L1038)/MAX(L1038-M1038,0.000000001),6) | O1038: =SUMPRODUCT(('01_Data'!$B1038:$AW1038<>"")*(1/(1+EXP(-(N1038-'03_Lap_b'!$B$20:$AW$20))))) | P1038: =SUMPRODUCT(('01_Data'!$B1038:$AW1038<>"")*(1/(1+EXP(-(N1038-'03_Lap_b'!$B$20:$AW$20))))^2) | Q1038: =MEDIAN(-6,N1038+(C1038-O1038)/MAX(O1038-P1038,0.000000001),6) | R1038: =SUMPRODUCT(('01_Data'!$B1038:$AW1038<>"")*(1/(1+EXP(-(Q1038-'03_Lap_b'!$B$25:$AW$25))))) | S1038: =SUMPRODUCT(('01_Data'!$B1038:$AW1038<>"")*(1/(1+EXP(-(Q1038-'03_Lap_b'!$B$25:$AW$25))))^2) | T1038: =MEDIAN(-6,Q1038+(C1038-R1038)/MAX(R1038-S1038,0.000000001),6) | U1038: =SUMPRODUCT(('01_Data'!$B1038:$AW1038<>"")*(1/(1+EXP(-(T1038-'03_Lap_b'!$B$30:$AW$30))))) | V1038: =SUMPRODUCT(('01_Data'!$B1038:$AW1038<>"")*(1/(1+EXP(-(T1038-'03_Lap_b'!$B$30:$AW$30))))^2) | W1038: =MEDIAN(-6,T1038+(C1038-U1038)/MAX(U1038-V1038,0.000000001),6) | X1038: =SUMPRODUCT(('01_Data'!$B1038:$AW1038<>"")*(1/(1+EXP(-(W1038-'03_Lap_b'!$B$35:$AW$35))))) | Y1038: =SUMPRODUCT(('01_Data'!$B1038:$AW1038<>"")*(1/(1+EXP(-(W1038-'03_Lap_b'!$B$35:$AW$35))))^2) | Z1038: =MEDIAN(-6,W1038+(C1038-X1038)/MAX(X1038-Y1038,0.000000001),6) | AA1038: =SUMPRODUCT(('01_Data'!$B1038:$AW1038<>"")*(1/(1+EXP(-(Z1038-'03_Lap_b'!$B$40:$AW$40))))) | AB1038: =SUMPRODUCT(('01_Data'!$B1038:$AW1038<>"")*(1/(1+EXP(-(Z1038-'03_Lap_b'!$B$40:$AW$40))))^2) | AC1038: =MEDIAN(-6,Z1038+(C1038-AA1038)/MAX(AA1038-AB1038,0.000000001),6)

Sheet 03_Lap_b
A1: Item → | B1: Câu 1 MC | C1: Câu 2 MC | D1: Câu 3 MC | E1: Câu 4 MC | F1: Câu 5 MC | G1: Câu 6 MC | H1: Câu 7 MC | I1: Câu 8 MC | J1: Câu 9 MC | K1: Câu 10 MC | L1: Câu 24 MC | M1: Câu 23 MC | N1: Câu 11 MC | O1: Câu 12 MC | P1: Câu 13 MC | Q1: Câu 22 MC | R1: Câu 16 MC | S1: Câu 17 MC | T1: Câu 18 MC | U1: Câu 14 MC | V1: Câu 15 MC | W1: Câu 19 MC | X1: Câu 20 MC | Y1: Câu 21 MC | Z1: Câu 25.a TF | AA1: Câu 25.b TF | AB1: Câu 25.c TF | AC1: Câu 25.d TF | AD1: Câu 27.a TF | AE1: Câu 27.b TF | AF1: Câu 27.c TF | AG1: Câu 27.d TF | AH1: Câu 26.a TF | AI1: Câu 26.b TF | AJ1: Câu 26.c TF | AK1: Câu 26.d TF | AL1: Câu 28.a TF | AM1: Câu 28.b TF | AN1: Câu 28.c TF | AO1: Câu 28.d TF | AP1: Câu 29.a TF | AQ1: Câu 29.b TF | AR1: Câu 29.c TF | AS1: Câu 29.d TF | AT1: Câu 30.a TF | AU1: Câu 30.b TF | AV1: Câu 30.c TF | AW1: Câu 30.d TF
B2: 208493209536 | C2: 208493412207 | D2: 208493634375 | E2: 208493806712 | F2: 208494503646 | G2: 208495066643 | H2: 208495459130 | I2: 208495984573 | J2: 208496326564 | K2: 208497043631 | L2: 208497697530 | M2: 208497947837 | N2: 208498680706 | O2: 208498750254 | P2: 208500103341 | Q2: 208500538567 | R2: 208501397853 | S2: 208501882621 | T2: 208502464537 | U2: 208518915377 | V2: 208519541200 | W2: 208519949207 | X2: 208520832930 | Y2: 208521276474 | Z2: 208529022568_a | AA2: 208529022568_b | AB2: 208529022568_c | AC2: 208529022568_d | AD2: 208560377855_a | AE2: 208560377855_b | AF2: 208560377855_c | AG2: 208560377855_d | AH2: 208572448723_a | AI2: 208572448723_b | AJ2: 208572448723_c | AK2: 208572448723_d | AL2: 208572588199_a | AM2: 208572588199_b | AN2: 208572588199_c | AO2: 208572588199_d | AP2: 208572673790_a | AQ2: 208572673790_b | AR2: 208572673790_c | AS2: 208572673790_d | AT2: 208576851532_a | AU2: 208576851532_b | AV2: 208576851532_c | AW2: 208576851532_d
A5: b0 (canh tâm) | B5: ='02_KhoiTao'!$I$2 | C5: ='02_KhoiTao'!$I$3 | D5: ='02_KhoiTao'!$I$4 | E5: ='02_KhoiTao'!$I$5 | F5: ='02_KhoiTao'!$I$6 | G5: ='02_KhoiTao'!$I$7 | H5: ='02_KhoiTao'!$I$8 | I5: ='02_KhoiTao'!$I$9 | J5: ='02_KhoiTao'!$I$10 | K5: ='02_KhoiTao'!$I$11 | L5: ='02_KhoiTao'!$I$12 | M5: ='02_KhoiTao'!$I$13 | N5: ='02_KhoiTao'!$I$14 | O5: ='02_KhoiTao'!$I$15 | P5: ='02_KhoiTao'!$I$16 | Q5: ='02_KhoiTao'!$I$17 | R5: ='02_KhoiTao'!$I$18 | S5: ='02_KhoiTao'!$I$19 | T5: ='02_KhoiTao'!$I$20 | U5: ='02_KhoiTao'!$I$21 | V5: ='02_KhoiTao'!$I$22 | W5: ='02_KhoiTao'!$I$23 | X5: ='02_KhoiTao'!$I$24 | Y5: ='02_KhoiTao'!$I$25 | Z5: ='02_KhoiTao'!$I$26 | AA5: ='02_KhoiTao'!$I$27 | AB5: ='02_KhoiTao'!$I$28 | AC5: ='02_KhoiTao'!$I$29 | AD5: ='02_KhoiTao'!$I$30 | AE5: ='02_KhoiTao'!$I$31 | AF5: ='02_KhoiTao'!$I$32 | AG5: ='02_KhoiTao'!$I$33 | AH5: ='02_KhoiTao'!$I$34 | AI5: ='02_KhoiTao'!$I$35 | AJ5: ='02_KhoiTao'!$I$36 | AK5: ='02_KhoiTao'!$I$37 | AL5: ='02_KhoiTao'!$I$38 | AM5: ='02_KhoiTao'!$I$39 | AN5: ='02_KhoiTao'!$I$40 | AO5: ='02_KhoiTao'!$I$41 | AP5: ='02_KhoiTao'!$I$42 | AQ5: ='02_KhoiTao'!$I$43 | AR5: ='02_KhoiTao'!$I$44 | AS5: ='02_KhoiTao'!$I$45 | AT5: ='02_KhoiTao'!$I$46 | AU5: ='02_KhoiTao'!$I$47 | AV5: ='02_KhoiTao'!$I$48 | AW5: ='02_KhoiTao'!$I$49
A7: ΣP vòng 1 | B7: =SUMPRODUCT(('01_Data'!B2:B1038<>"")*(1/(1+EXP(-('03_Lap_Theta'!$H$2:$H$1038-B5))))) | C7: =SUMPRODUCT(('01_Data'!C2:C1038<>"")*(1/(1+EXP(-('03_Lap_Theta'!$H$2:$H$1038-C5))))) | D7: =SUMPRODUCT(('01_Data'!D2:D1038<>"")*(1/(1+EXP(-('03_Lap_Theta'!$H$2:$H$1038-D5))))) | E7: =SUMPRODUCT(('01_Data'!E2:E1038<>"")*(1/(1+EXP(-('03_Lap_Theta'!$H$2:$H$1038-E5))))) | F7: =SUMPRODUCT(('01_Data'!F2:F1038<>"")*(1/(1+EXP(-('03_Lap_Theta'!$H$2:$H$1038-F5))))) | G7: =SUMPRODUCT(('01_Data'!G2:G1038<>"")*(1/(1+EXP(-('03_Lap_Theta'!$H$2:$H$1038-G5))))) | H7: =SUMPRODUCT(('01_Data'!H2:H1038<>"")*(1/(1+EXP(-('03_Lap_Theta'!$H$2:$H$1038-H5))))) | I7: =SUMPRODUCT(('01_Data'!I2:I1038<>"")*(1/(1+EXP(-('03_Lap_Theta'!$H$2:$H$1038-I5))))) | ... AW7: =SUMPRODUCT(('01_Data'!AW2:AW1038<>"")*(1/(1+EXP(-('03_Lap_Theta'!$H$2:$H$1038-AW5)))))
A8: ΣP² vòng 1 | B8: =SUMPRODUCT(('01_Data'!B2:B1038<>"")*(1/(1+EXP(-('03_Lap_Theta'!$H$2:$H$1038-B5))))^2) | C8: =SUMPRODUCT(('01_Data'!C2:C1038<>"")*(1/(1+EXP(-('03_Lap_Theta'!$H$2:$H$1038-C5))))^2) | D8: =SUMPRODUCT(('01_Data'!D2:D1038<>"")*(1/(1+EXP(-('03_Lap_Theta'!$H$2:$H$1038-D5))))^2) | E8: =SUMPRODUCT(('01_Data'!E2:E1038<>"")*(1/(1+EXP(-('03_Lap_Theta'!$H$2:$H$1038-E5))))^2) | F8: =SUMPRODUCT(('01_Data'!F2:F1038<>"")*(1/(1+EXP(-('03_Lap_Theta'!$H$2:$H$1038-F5))))^2) | G8: =SUMPRODUCT(('01_Data'!G2:G1038<>"")*(1/(1+EXP(-('03_Lap_Theta'!$H$2:$H$1038-G5))))^2) | H8: =SUMPRODUCT(('01_Data'!H2:H1038<>"")*(1/(1+EXP(-('03_Lap_Theta'!$H$2:$H$1038-H5))))^2) | I8: =SUMPRODUCT(('01_Data'!I2:I1038<>"")*(1/(1+EXP(-('03_Lap_Theta'!$H$2:$H$1038-I5))))^2) | ... AW8: =SUMPRODUCT(('01_Data'!AW2:AW1038<>"")*(1/(1+EXP(-('03_Lap_Theta'!$H$2:$H$1038-AW5))))^2)
